Workbook

Sheet Matriz
A1: Matriz de Procesos Automatizables de T&L
A2: A. IDENTIFICACIÓN (aplica a todos) | I2: B. CARACTERIZACIÓN DEL PROCESO (aplica a todos) | AF2: C. EVALUACIÓN DEL DESARROLLO (sólo Tipo = En curso) | AW2: D. DISEÑO DE LA AUTOMATIZACIÓN (sólo Tipo = Nuevo) | BG2: E. PRIORIZACIÓN
A3: ID | B3: Tipo | C3: Ámbito | D3: Sector / Área | E3: Proceso o desarrollo | F3: Referente entrevistado | G3: Descripción breve | H3: Destinatario | I3: Frecuencia | J3: Ejecuciones por año y por cliente | K3: Cantidad de clientes/entidades | L3: Duración actual por ejecución (hs) | M3: Personas involucradas | N3: Horas-persona anuales | O3: % Junior | P3: % Senior | Q3: % Gerente | R3: % Socio | S3: Suma (control) | T3: % Gerente + Socio | U3: Índice de seniority (1-4) | V3: Amplitud de roles (1-4) | W3: Estacionalidad (meses pico) | X3: Procesos con los que se entrelaza | Y3: % data entry vs. criterio | Z3: ¿Genera cuello de botella? | AA3: Naturaleza del trabajo | AB3: Sistemas y herramientas actuales | AC3: Criticidad (1-5) | AD3: Riesgo de fiscalización (1-5) | AE3: Nivel de automatización actual (0-4) | AF3: Tecnología utilizada | AG3: Dónde se ejecuta | AH3: Horas incurridas en el desarrollo | AI3: Responsable de mantenimiento | AJ3: Puesta en producción | AK3: Usuarios habilitados | AL3: Usuarios activos | AM3: Nivel de uso (%) | AN3: Duración ANTES del desarrollo (hs) | AO3: Reducción de duración (%) | AP3: Horas-persona ahorradas / año | AQ3: Tasa error usuario (%) | AR3: Tasa error herramienta (%) | AS3: Gestión de errores (1-4) | AT3: Independencia respecto de IT | AU3: Satisfacción usuarios (1-5) | AV3: Score de Salud del Desarrollo | AW3: Grado de automatizabilidad (1-5) | AX3: Tipo de automatización sugerida | AY3: Herramienta sugerida | AZ3: Complejidad de implementación (1-5) | BA3: Esfuerzo estimado (hs de desarrollo) | BB3: Reducción de duración estimada (%) | BC3: Horas-persona ahorro estimado / año | BD3: Replicable a clientes | BE3: Dependencias / prerrequisitos | BF3: Score de Priorización | BG3: Impacto (0-10) | BH3: Esfuerzo (0-10) | BI3: Cuadrante impacto vs. esfuerzo | BJ3: Prioridad / Estado | BK3: Comentarios / próximos pasos
A4: 1 | B4: En curso | C4: De área | D4: Business Tax | E4: Liquidación de Impuesto a las Ganancias | F4: Franco Vassallo y | G4: Papel de trabajo en Excel con macros: parametrización de cuentas, reversión automática de saldos, cálculo del ajuste por inflación y armado de los ajustes de la DDJJ. | H4: Interno | I4: Anual | J4: 1 | N4: =IF($E4="","",J4*K4*L4*M4) -> 0 | S4: =IF($E4="","",O4+P4+Q4+R4) -> 0 | T4: =IF($E4="","",Q4+R4) -> 0 | U4: =IF($E4="","",IFERROR(ROUND((O4*[1]Parámetros!$B$29+P4*[1]Parámetros!$B$30+Q4*[1]Parámetros!$B$31+R4*[1]Parámetros!$B$32)/S4,2),"")) | V4: =IF($E4="","",IF(O4>0,1,0)+IF(P4>0,1,0)+IF(Q4>0,1,0)+IF(R4>0,1,0)) -> 0 | W4: Abr-May (clientes con cierre en diciembre) | X4: CTF (bienes de uso); templates teóricos; valuación de inversiones financieras | Z4: Sí | AA4: Compilación entre Excel y otras herramientas | AB4: Excel + macros | AE4: 3 | AF4: Excel + macros (VBA) — a confirmar con IT | AG4: Notebook del usuario | AM4: =IF($B4<>"En curso","",IFERROR(AL4/AK4,"")) | AO4: =IF($B4<>"En curso","",IFERROR((AN4-L4)/AN4,"")) | AP4: =IF($B4<>"En curso","",IFERROR((AN4-L4)*J4*K4*M4,"")) -> 0 | AV4: =IF($B4<>"En curso","",IF(COUNT(AK4:AL4)+COUNT(AN4)+COUNT(AQ4:AR4)=0,"",ROUND(IFERROR(N(AM4),0)*10*[1]Parámetros!$B$18+MAX(0,IFERROR(N(AO4),0))*10*[1]Parámetros!$B$19+MAX(0,1-IFERROR(N(AQ4),0)-IFERROR(N(AR4),0))*10*[1]Parámetros!$B$20+IFERROR(N(AS4),0)/4*10*[1]Parámetros!$B$21+IFERROR(N(AU4),0)/5*10*[1]Parámetros!$B$22,2))) | BC4: =IF($B4<>"Nuevo","",IFERROR(N4*BB4,"")) | BF4: =IF($B4<>"Nuevo","",IF(N(N4)=0,"",ROUND(MAX(0,MIN(10,MAX(0,IFERROR(N(N4)/MAX($N$4:$N$58),0)*10*[1]Parámetros!$B$5+IFERROR(N(AW4),0)*2*[1]Parámetros!$B$6+IFERROR(N(AC4),0)*2*[1]Parámetros!$B$7+IFERROR(INDEX([1]Parámetros!$B$37:$B$48,MATCH(D4,[1]Parámetros!$A$37:$A$48,0)),3)*2*[1]Parámetros!$B$8+IFERROR(N(AD4),0)*2*[1]Parámetros!$B$9+IFERROR(N(U4),0)*2.5*[1]Parámetros!$B$10+IFERROR(N(V4),0)*2.5*[1]Parámetros!$B$11+IF(Z4="Sí",10,0)*[1]Parámetros!$B$12)/[1]Parámetros!$B$14)-IFERROR(N(AZ4),0)*2*[1]Parámetros!$B$13),2))) | BG4: =IF($B4<>"Nuevo","",IF(N(N4)=0,"",ROUND(MIN(10,MAX(0,IFERROR(N(N4)/MAX($N$4:$N$58),0)*10*[1]Parámetros!$B$5+IFERROR(N(AW4),0)*2*[1]Parámetros!$B$6+IFERROR(N(AC4),0)*2*[1]Parámetros!$B$7+IFERROR(INDEX([1]Parámetros!$B$37:$B$48,MATCH(D4,[1]Parámetros!$A$37:$A$48,0)),3)*2*[1]Parámetros!$B$8+IFERROR(N(AD4),0)*2*[1]Parámetros!$B$9+IFERROR(N(U4),0)*2.5*[1]Parámetros!$B$10+IFERROR(N(V4),0)*2.5*[1]Parámetros!$B$11+IF(Z4="Sí",10,0)*[1]Parámetros!$B$12)/[1]Parámetros!$B$14),2))) | BH4: =IF($B4<>"Nuevo","",ROUND(IFERROR(AZ4,0)*2,2)) | BI4: =IF($B4<>"Nuevo","",IF(NOT(ISNUMBER(BG4)),"",IF(BG4>=5,IF(BH4<=5,"Quick win","Estructural"),IF(BH4<=5,"Mejora marginal","Descartar / replantear")))) | BJ4: =IF($E4="","",IF($B4="Nuevo",IF(NOT(ISNUMBER(BF4)),"",IF(BF4>=6,"Alta",IF(BF4>=4,"Media","Baja"))),IF($B4="En curso",IF(NOT(ISNUMBER(AV4)),"",IF(AV4>=7,"Saludable",IF(AV4>=5,"A revisar","Crítico"))),""))) | BK4: Proyecto de 3-4 años; el último año concentró la mayor parte del avance. La reversión automática de saldos se activa recién en el 2° año de cada cliente (el 1° exige parametrizar cuentas). PENDIENTE: cantidad de clientes, duración por ejecución, reparto por seniority, usuarios habilitados/activos, duración previa, tasas de error, satisfacción y horas de desarrollo. El Score de Salud no es representativo hasta cargar el bloque C. Oportunidad mencionada: validaciones con IA y lectura de balance en PDF.
A5: 2 | B5: En curso | C5: De área | D5: Business Tax | E5: CTF — Valuación impositiva de bienes de uso | F5: (champion de Business Tax) | G5: Archivo aparte que calcula la amortización impositiva y la actualización por IPC de bienes de uso, con histórico de altas/bajas y prueba global de control. Alimenta el papel de Ganancias. | H5: Interno | I5: Anual | J5: 1 | N5: =IF($E5="","",J5*K5*L5*M5) -> 0 | S5: =IF($E5="","",O5+P5+Q5+R5) -> 0 | T5: =IF($E5="","",Q5+R5) -> 0 | U5: =IF($E5="","",IFERROR(ROUND((O5*[1]Parámetros!$B$29+P5*[1]Parámetros!$B$30+Q5*[1]Parámetros!$B$31+R5*[1]Parámetros!$B$32)/S5,2),"")) | V5: =IF($E5="","",IF(O5>0,1,0)+IF(P5>0,1,0)+IF(Q5>0,1,0)+IF(R5>0,1,0)) -> 0 | W5: Abr-May (clientes con cierre en diciembre) | X5: Liquidación de Impuesto a las Ganancias | Z5: Sí | AA5: Cálculo o procesamiento | AB5: Excel + macros | AE5: 3 | AF5: Excel + macros (VBA) — a confirmar con IT | AG5: Notebook del usuario | AM5: =IF($B5<>"En curso","",IFERROR(AL5/AK5,"")) | AO5: =IF($B5<>"En curso","",IFERROR((AN5-L5)/AN5,"")) | AP5: =IF($B5<>"En curso","",IFERROR((AN5-L5)*J5*K5*M5,"")) -> 0 | AS5: 4 | AV5: =IF($B5<>"En curso","",IF(COUNT(AK5:AL5)+COUNT(AN5)+COUNT(AQ5:AR5)=0,"",ROUND(IFERROR(N(AM5),0)*10*[1]Parámetros!$B$18+MAX(0,IFERROR(N(AO5),0))*10*[1]Parámetros!$B$19+MAX(0,1-IFERROR(N(AQ5),0)-IFERROR(N(AR5),0))*10*[1]Parámetros!$B$20+IFERROR(N(AS5),0)/4*10*[1]Parámetros!$B$21+IFERROR(N(AU5),0)/5*10*[1]Parámetros!$B$22,2))) | BC5: =IF($B5<>"Nuevo","",IFERROR(N5*BB5,"")) | BF5: =IF($B5<>"Nuevo","",IF(N(N5)=0,"",ROUND(MAX(0,MIN(10,MAX(0,IFERROR(N(N5)/MAX($N$4:$N$58),0)*10*[1]Parámetros!$B$5+IFERROR(N(AW5),0)*2*[1]Parámetros!$B$6+IFERROR(N(AC5),0)*2*[1]Parámetros!$B$7+IFERROR(INDEX([1]Parámetros!$B$37:$B$48,MATCH(D5,[1]Parámetros!$A$37:$A$48,0)),3)*2*[1]Parámetros!$B$8+IFERROR(N(AD5),0)*2*[1]Parámetros!$B$9+IFERROR(N(U5),0)*2.5*[1]Parámetros!$B$10+IFERROR(N(V5),0)*2.5*[1]Parámetros!$B$11+IF(Z5="Sí",10,0)*[1]Parámetros!$B$12)/[1]Parámetros!$B$14)-IFERROR(N(AZ5),0)*2*[1]Parámetros!$B$13),2))) | BG5: =IF($B5<>"Nuevo","",IF(N(N5)=0,"",ROUND(MIN(10,MAX(0,IFERROR(N(N5)/MAX($N$4:$N$58),0)*10*[1]Parámetros!$B$5+IFERROR(N(AW5),0)*2*[1]Parámetros!$B$6+IFERROR(N(AC5),0)*2*[1]Parámetros!$B$7+IFERROR(INDEX([1]Parámetros!$B$37:$B$48,MATCH(D5,[1]Parámetros!$A$37:$A$48,0)),3)*2*[1]Parámetros!$B$8+IFERROR(N(AD5),0)*2*[1]Parámetros!$B$9+IFERROR(N(U5),0)*2.5*[1]Parámetros!$B$10+IFERROR(N(V5),0)*2.5*[1]Parámetros!$B$11+IF(Z5="Sí",10,0)*[1]Parámetros!$B$12)/[1]Parámetros!$B$14),2))) | BH5: =IF($B5<>"Nuevo","",ROUND(IFERROR(AZ5,0)*2,2)) | BI5: =IF($B5<>"Nuevo","",IF(NOT(ISNUMBER(BG5)),"",IF(BG5>=5,IF(BH5<=5,"Quick win","Estructural"),IF(BH5<=5,"Mejora marginal","Descartar / replantear")))) | BJ5: =IF($E5="","",IF($B5="Nuevo",IF(NOT(ISNUMBER(BF5)),"",IF(BF5>=6,"Alta",IF(BF5>=4,"Media","Baja"))),IF($B5="En curso",IF(NOT(ISNUMBER(AV5)),"",IF(AV5>=7,"Saludable",IF(AV5>=5,"A revisar","Crítico"))),""))) | BK5: Casi terminado, en ronda de feedback. Volumen alto: hay compañías con ~500.000 bienes. La prueba global (saldo inicial + altas − bajas − amortización = 0) devuelve un error accionable y el usuario lo resuelve sin escalar a IT. Valor agregado adicional: subcódigos de obra en curso permiten actualizar por inflación desde cada erogación, lo que hoy se pierde. Sólo se necesitan 3 datos del cliente (costo, vida útil, fecha); el copy-paste no es el cuello de botella. PENDIENTE: clientes, duración, reparto por seniority y todo el resto del bloque C.
A6: 3 | B6: En curso | C6: De área | D6: Business Tax | E6: Templates teóricos por ajuste | F6: (champion de Business Tax) | G6: Repositorio de marco normativo, encuadre teórico y ejemplos por cada ajuste de la DDJJ de Ganancias, a vincular al papel de trabajo. | H6: Interno | I6: Ad-hoc | N6: =IF($E6="","",J6*K6*L6*M6) -> 0 | S6: =IF($E6="","",O6+P6+Q6+R6) -> 0 | T6: =IF($E6="","",Q6+R6) -> 0 | U6: =IF($E6="","",IFERROR(ROUND((O6*[1]Parámetros!$B$29+P6*[1]Parámetros!$B$30+Q6*[1]Parámetros!$B$31+R6*[1]Parámetros!$B$32)/S6,2),"")) | V6: =IF($E6="","",IF(O6>0,1,0)+IF(P6>0,1,0)+IF(Q6>0,1,0)+IF(R6>0,1,0)) -> 0 | W6: Abr-May (uso concentrado en temporada) | X6: Liquidación de Impuesto a las Ganancias | AA6: Búsqueda de información | AB6: Excel / Word | AE6: 2 | AF6: Excel | AG6: Notebook del usuario | AM6: =IF($B6<>"En curso","",IFERROR(AL6/AK6,"")) | AO6: =IF($B6<>"En curso","",IFERROR((AN6-L6)/AN6,"")) | AP6: =IF($B6<>"En curso","",IFERROR((AN6-L6)*J6*K6*M6,"")) -> 0 | AV6: =IF($B6<>"En curso","",IF(COUNT(AK6:AL6)+COUNT(AN6)+COUNT(AQ6:AR6)=0,"",ROUND(IFERROR(N(AM6),0)*10*[1]Parámetros!$B$18+MAX(0,IFERROR(N(AO6),0))*10*[1]Parámetros!$B$19+MAX(0,1-IFERROR(N(AQ6),0)-IFERROR(N(AR6),0))*10*[1]Parámetros!$B$20+IFERROR(N(AS6),0)/4*10*[1]Parámetros!$B$21+IFERROR(N(AU6),0)/5*10*[1]Parámetros!$B$22,2))) | BC6: =IF($B6<>"Nuevo","",IFERROR(N6*BB6,"")) | BF6: =IF($B6<>"Nuevo","",IF(N(N6)=0,"",ROUND(MAX(0,MIN(10,MAX(0,IFERROR(N(N6)/MAX($N$4:$N$58),0)*10*[1]Parámetros!$B$5+IFERROR(N(AW6),0)*2*[1]Parámetros!$B$6+IFERROR(N(AC6),0)*2*[1]Parámetros!$B$7+IFERROR(INDEX([1]Parámetros!$B$37:$B$48,MATCH(D6,[1]Parámetros!$A$37:$A$48,0)),3)*2*[1]Parámetros!$B$8+IFERROR(N(AD6),0)*2*[1]Parámetros!$B$9+IFERROR(N(U6),0)*2.5*[1]Parámetros!$B$10+IFERROR(N(V6),0)*2.5*[1]Parámetros!$B$11+IF(Z6="Sí",10,0)*[1]Parámetros!$B$12)/[1]Parámetros!$B$14)-IFERROR(N(AZ6),0)*2*[1]Parámetros!$B$13),2))) | BG6: =IF($B6<>"Nuevo","",IF(N(N6)=0,"",ROUND(MIN(10,MAX(0,IFERROR(N(N6)/MAX($N$4:$N$58),0)*10*[1]Parámetros!$B$5+IFERROR(N(AW6),0)*2*[1]Parámetros!$B$6+IFERROR(N(AC6),0)*2*[1]Parámetros!$B$7+IFERROR(INDEX([1]Parámetros!$B$37:$B$48,MATCH(D6,[1]Parámetros!$A$37:$A$48,0)),3)*2*[1]Parámetros!$B$8+IFERROR(N(AD6),0)*2*[1]Parámetros!$B$9+IFERROR(N(U6),0)*2.5*[1]Parámetros!$B$10+IFERROR(N(V6),0)*2.5*[1]Parámetros!$B$11+IF(Z6="Sí",10,0)*[1]Parámetros!$B$12)/[1]Parámetros!$B$14),2))) | BH6: =IF($B6<>"Nuevo","",ROUND(IFERROR(AZ6,0)*2,2)) | BI6: =IF($B6<>"Nuevo","",IF(NOT(ISNUMBER(BG6)),"",IF(BG6>=5,IF(BH6<=5,"Quick win","Estructural"),IF(BH6<=5,"Mejora marginal","Descartar / replantear")))) | BJ6: =IF($E6="","",IF($B6="Nuevo",IF(NOT(ISNUMBER(BF6)),"",IF(BF6>=6,"Alta",IF(BF6>=4,"Media","Baja"))),IF($B6="En curso",IF(NOT(ISNUMBER(AV6)),"",IF(AV6>=7,"Saludable",IF(AV6>=5,"A revisar","Crítico"))),""))) | BK6: Contenido armado (un tema por analista, con revisión). Falta unificar formato y, sobre todo, integrarlo: hoja oculta del papel de trabajo + macro de vínculo desde cada ajuste. No se incorporó jurisprudencia. Oportunidad: usar el conjunto como base de conocimiento de un agente consultable desde el propio papel. PENDIENTE: bloque C completo y frecuencia real de uso.
A7: 4 | B7: En curso | C7: De área | D7: Business Tax | E7: Novedades impositivas — bot de boletines | F7: (champion de Business Tax) | G7: Descarga semanal de los boletines oficiales de las 24 provincias y el nacional, filtro por ministerio + palabras clave y armado de un reporte de novedades relevantes. | H7: Interno | I7: Semanal | J7: 52 | K7: 25 | N7: =IF($E7="","",J7*K7*L7*M7) -> 0 | S7: =IF($E7="","",O7+P7+Q7+R7) -> 0 | T7: =IF($E7="","",Q7+R7) -> 0 | U7: =IF($E7="","",IFERROR(ROUND((O7*[1]Parámetros!$B$29+P7*[1]Parámetros!$B$30+Q7*[1]Parámetros!$B$31+R7*[1]Parámetros!$B$32)/S7,2),"")) | V7: =IF($E7="","",IF(O7>0,1,0)+IF(P7>0,1,0)+IF(Q7>0,1,0)+IF(R7>0,1,0)) -> 0 | W7: Sin estacionalidad marcada | AA7: Búsqueda de información | AB7: Python + Playwright | AE7: 2 | AF7: Python + Playwright | AG7: Notebook del usuario | AM7: =IF($B7<>"En curso","",IFERROR(AL7/AK7,"")) | AO7: =IF($B7<>"En curso","",IFERROR((AN7-L7)/AN7,"")) | AP7: =IF($B7<>"En curso","",IFERROR((AN7-L7)*J7*K7*M7,"")) -> 0 | AV7: =IF($B7<>"En curso","",IF(COUNT(AK7:AL7)+COUNT(AN7)+COUNT(AQ7:AR7)=0,"",ROUND(IFERROR(N(AM7),0)*10*[1]Parámetros!$B$18+MAX(0,IFERROR(N(AO7),0))*10*[1]Parámetros!$B$19+MAX(0,1-IFERROR(N(AQ7),0)-IFERROR(N(AR7),0))*10*[1]Parámetros!$B$20+IFERROR(N(AS7),0)/4*10*[1]Parámetros!$B$21+IFERROR(N(AU7),0)/5*10*[1]Parámetros!$B$22,2))) | BC7: =IF($B7<>"Nuevo","",IFERROR(N7*BB7,"")) | BF7: =IF($B7<>"Nuevo","",IF(N(N7)=0,"",ROUND(MAX(0,MIN(10,MAX(0,IFERROR(N(N7)/MAX($N$4:$N$58),0)*10*[1]Parámetros!$B$5+IFERROR(N(AW7),0)*2*[1]Parámetros!$B$6+IFERROR(N(AC7),0)*2*[1]Parámetros!$B$7+IFERROR(INDEX([1]Parámetros!$B$37:$B$48,MATCH(D7,[1]Parámetros!$A$37:$A$48,0)),3)*2*[1]Parámetros!$B$8+IFERROR(N(AD7),0)*2*[1]Parámetros!$B$9+IFERROR(N(U7),0)*2.5*[1]Parámetros!$B$10+IFERROR(N(V7),0)*2.5*[1]Parámetros!$B$11+IF(Z7="Sí",10,0)*[1]Parámetros!$B$12)/[1]Parámetros!$B$14)-IFERROR(N(AZ7),0)*2*[1]Parámetros!$B$13),2))) | BG7: =IF($B7<>"Nuevo","",IF(N(N7)=0,"",ROUND(MIN(10,MAX(0,IFERROR(N(N7)/MAX($N$4:$N$58),0)*10*[1]Parámetros!$B$5+IFERROR(N(AW7),0)*2*[1]Parámetros!$B$6+IFERROR(N(AC7),0)*2*[1]Parámetros!$B$7+IFERROR(INDEX([1]Parámetros!$B$37:$B$48,MATCH(D7,[1]Parámetros!$A$37:$A$48,0)),3)*2*[1]Parámetros!$B$8+IFERROR(N(AD7),0)*2*[1]Parámetros!$B$9+IFERROR(N(U7),0)*2.5*[1]Parámetros!$B$10+IFERROR(N(V7),0)*2.5*[1]Parámetros!$B$11+IF(Z7="Sí",10,0)*[1]Parámetros!$B$12)/[1]Parámetros!$B$14),2))) | BH7: =IF($B7<>"Nuevo","",ROUND(IFERROR(AZ7,0)*2,2)) | BI7: =IF($B7<>"Nuevo","",IF(NOT(ISNUMBER(BG7)),"",IF(BG7>=5,IF(BH7<=5,"Quick win","Estructural"),IF(BH7<=5,"Mejora marginal","Descartar / replantear")))) | BJ7: =IF($E7="","",IF($B7="Nuevo",IF(NOT(ISNUMBER(BF7)),"",IF(BF7>=6,"Alta",IF(BF7>=4,"Media","Baja"))),IF($B7="En curso",IF(NOT(ISNUMBER(AV7)),"",IF(AV7>=7,"Saludable",IF(AV7>=5,"A revisar","Crítico"))),""))) | BK7: Desarrollado in-house en ~3-4 meses. Criterio de filtro: ministerio + mínimo 2 palabras clave (con 1 descarta, para evitar ruido). Se prefieren falsos positivos a omisiones; cada semana se suman palabras clave. Limitaciones: PDFs escaneados con OCR (San Juan, Santa Cruz) y ausencia de resumen/envío. Próximo paso bloqueado por la aprobación de agentes de IA. NOTA: 'Cantidad de clientes' se cargó como 25 jurisdicciones (unidad de corrida), no como clientes. PENDIENTE: horas semanales que insume hoy la revisión manual y el armado del mail.
A8: 5 | B8: Nuevo | C8: De área | D8: Business Tax | E8: Valuación de inversiones financieras | F8: (champion de Business Tax) | G8: Valuación impositiva de instrumentos financieros para la DDJJ de Ganancias. Sólo están automatizados los fondos comunes de inversión. | H8: Interno | I8: Anual | J8: 1 | N8: =IF($E8="","",J8*K8*L8*M8) -> 0 | S8: =IF($E8="","",O8+P8+Q8+R8) -> 0 | T8: =IF($E8="","",Q8+R8) -> 0 | U8: =IF($E8="","",IFERROR(ROUND((O8*[1]Parámetros!$B$29+P8*[1]Parámetros!$B$30+Q8*[1]Parámetros!$B$31+R8*[1]Parámetros!$B$32)/S8,2),"")) | V8: =IF($E8="","",IF(O8>0,1,0)+IF(P8>0,1,0)+IF(Q8>0,1,0)+IF(R8>0,1,0)) -> 0 | W8: Abr-May (clientes con cierre en diciembre) | X8: Liquidación de Impuesto a las Ganancias | AA8: Búsqueda de información | AB8: Excel / información del cliente / cotizaciones de internet | AE8: 1 | AM8: =IF($B8<>"En curso","",IFERROR(AL8/AK8,"")) | AO8: =IF($B8<>"En curso","",IFERROR((AN8-L8)/AN8,"")) | AP8: =IF($B8<>"En curso","",IFERROR((AN8-L8)*J8*K8*M8,"")) | AV8: =IF($B8<>"En curso","",IF(COUNT(AK8:AL8)+COUNT(AN8)+COUNT(AQ8:AR8)=0,"",ROUND(IFERROR(N(AM8),0)*10*[1]Parámetros!$B$18+MAX(0,IFERROR(N(AO8),0))*10*[1]Parámetros!$B$19+MAX(0,1-IFERROR(N(AQ8),0)-IFERROR(N(AR8),0))*10*[1]Parámetros!$B$20+IFERROR(N(AS8),0)/4*10*[1]Parámetros!$B$21+IFERROR(N(AU8),0)/5*10*[1]Parámetros!$B$22,2))) | AW8: 4 | AX8: Workflow + Agente | AY8: Python + Agentes de IA | AZ8: 4 | BC8: =IF($B8<>"Nuevo","",IFERROR(N8*BB8,"")) -> 0 | BE8: Definir fuentes de cotizaciones y su acceso; criterios de valuación por tipo de instrumento. | BF8: =IF($B8<>"Nuevo","",IF(N(N8)=0,"",ROUND(MAX(0,MIN(10,MAX(0,IFERROR(N(N8)/MAX($N$4:$N$58),0)*10*[1]Parámetros!$B$5+IFERROR(N(AW8),0)*2*[1]Parámetros!$B$6+IFERROR(N(AC8),0)*2*[1]Parámetros!$B$7+IFERROR(INDEX([1]Parámetros!$B$37:$B$48,MATCH(D8,[1]Parámetros!$A$37:$A$48,0)),3)*2*[1]Parámetros!$B$8+IFERROR(N(AD8),0)*2*[1]Parámetros!$B$9+IFERROR(N(U8),0)*2.5*[1]Parámetros!$B$10+IFERROR(N(V8),0)*2.5*[1]Parámetros!$B$11+IF(Z8="Sí",10,0)*[1]Parámetros!$B$12)/[1]Parámetros!$B$14)-IFERROR(N(AZ8),0)*2*[1]Parámetros!$B$13),2))) | BG8: =IF($B8<>"Nuevo","",IF(N(N8)=0,"",ROUND(MIN(10,MAX(0,IFERROR(N(N8)/MAX($N$4:$N$58),0)*10*[1]Parámetros!$B$5+IFERROR(N(AW8),0)*2*[1]Parámetros!$B$6+IFERROR(N(AC8),0)*2*[1]Parámetros!$B$7+IFERROR(INDEX([1]Parámetros!$B$37:$B$48,MATCH(D8,[1]Parámetros!$A$37:$A$48,0)),3)*2*[1]Parámetros!$B$8+IFERROR(N(AD8),0)*2*[1]Parámetros!$B$9+IFERROR(N(U8),0)*2.5*[1]Parámetros!$B$10+IFERROR(N(V8),0)*2.5*[1]Parámetros!$B$11+IF(Z8="Sí",10,0)*[1]Parámetros!$B$12)/[1]Parámetros!$B$14),2))) | BH8: =IF($B8<>"Nuevo","",ROUND(IFERROR(AZ8,0)*2,2)) -> 8 | BI8: =IF($B8<>"Nuevo","",IF(NOT(ISNUMBER(BG8)),"",IF(BG8>=5,IF(BH8<=5,"Quick win","Estructural"),IF(BH8<=5,"Mejora marginal","Descartar / replantear")))) | BJ8: =IF($E8="","",IF($B8="Nuevo",IF(NOT(ISNUMBER(BF8)),"",IF(BF8>=6,"Alta",IF(BF8>=4,"Media","Baja"))),IF($B8="En curso",IF(NOT(ISNUMBER(AV8)),"",IF(AV8>=7,"Saludable",IF(AV8>=5,"A revisar","Crítico"))),""))) | BK8: Junto con CTF, es la pata que más horas de análisis consume en el pico. El sector la considera perfectamente automatizable. Grado de automatizabilidad y complejidad son propuesta preliminar del analista, a validar. PENDIENTE: volumen (clientes, duración, personas) — sin eso el Score de Priorización subestima el impacto.
A9: 6 | B9: Nuevo | C9: General | D9: Business Tax | E9: Repositorio y agente de consultas de consultoría | F9: (champion de Business Tax) | G9: Base de conocimiento de memos, mails e informes de consultas ya respondidas, consultable ante una consulta nueva, con trazabilidad al documento original. | H9: Interno | I9: Ad-hoc | N9: =IF($E9="","",J9*K9*L9*M9) -> 0 | S9: =IF($E9="","",O9+P9+Q9+R9) -> 0 | T9: =IF($E9="","",Q9+R9) -> 0 | U9: =IF($E9="","",IFERROR(ROUND((O9*[1]Parámetros!$B$29+P9*[1]Parámetros!$B$30+Q9*[1]Parámetros!$B$31+R9*[1]Parámetros!$B$32)/S9,2),"")) | V9: =IF($E9="","",IF(O9>0,1,0)+IF(P9>0,1,0)+IF(Q9>0,1,0)+IF(R9>0,1,0)) -> 0 | AA9: Búsqueda de información | AB9: Carpeta en Teams | AE9: 1 | AM9: =IF($B9<>"En curso","",IFERROR(AL9/AK9,"")) | AO9: =IF($B9<>"En curso","",IFERROR((AN9-L9)/AN9,"")) | AP9: =IF($B9<>"En curso","",IFERROR((AN9-L9)*J9*K9*M9,"")) | AV9: =IF($B9<>"En curso","",IF(COUNT(AK9:AL9)+COUNT(AN9)+COUNT(AQ9:AR9)=0,"",ROUND(IFERROR(N(AM9),0)*10*[1]Parámetros!$B$18+MAX(0,IFERROR(N(AO9),0))*10*[1]Parámetros!$B$19+MAX(0,1-IFERROR(N(AQ9),0)-IFERROR(N(AR9),0))*10*[1]Parámetros!$B$20+IFERROR(N(AS9),0)/4*10*[1]Parámetros!$B$21+IFERROR(N(AU9),0)/5*10*[1]Parámetros!$B$22,2))) | AW9: 3 | AX9: Agente | AY9: Python + Agentes de IA | AZ9: 3 | BC9: =IF($B9<>"Nuevo","",IFERROR(N9*BB9,"")) -> 0 | BE9: Aprobación para el uso de agentes de IA; consolidación de la base de memos; criterio de confidencialidad por cliente. | BF9: =IF($B9<>"Nuevo","",IF(N(N9)=0,"",ROUND(MAX(0,MIN(10,MAX(0,IFERROR(N(N9)/MAX($N$4:$N$58),0)*10*[1]Parámetros!$B$5+IFERROR(N(AW9),0)*2*[1]Parámetros!$B$6+IFERROR(N(AC9),0)*2*[1]Parámetros!$B$7+IFERROR(INDEX([1]Parámetros!$B$37:$B$48,MATCH(D9,[1]Parámetros!$A$37:$A$48,0)),3)*2*[1]Parámetros!$B$8+IFERROR(N(AD9),0)*2*[1]Parámetros!$B$9+IFERROR(N(U9),0)*2.5*[1]Parámetros!$B$10+IFERROR(N(V9),0)*2.5*[1]Parámetros!$B$11+IF(Z9="Sí",10,0)*[1]Parámetros!$B$12)/[1]Parámetros!$B$14)-IFERROR(N(AZ9),0)*2*[1]Parámetros!$B$13),2))) | BG9: =IF($B9<>"Nuevo","",IF(N(N9)=0,"",ROUND(MIN(10,MAX(0,IFERROR(N(N9)/MAX($N$4:$N$58),0)*10*[1]Parámetros!$B$5+IFERROR(N(AW9),0)*2*[1]Parámetros!$B$6+IFERROR(N(AC9),0)*2*[1]Parámetros!$B$7+IFERROR(INDEX([1]Parámetros!$B$37:$B$48,MATCH(D9,[1]Parámetros!$A$37:$A$48,0)),3)*2*[1]Parámetros!$B$8+IFERROR(N(AD9),0)*2*[1]Parámetros!$B$9+IFERROR(N(U9),0)*2.5*[1]Parámetros!$B$10+IFERROR(N(V9),0)*2.5*[1]Parámetros!$B$11+IF(Z9="Sí",10,0)*[1]Parámetros!$B$12)/[1]Parámetros!$B$14),2))) | BH9: =IF($B9<>"Nuevo","",ROUND(IFERROR(AZ9,0)*2,2)) -> 6 | BI9: =IF($B9<>"Nuevo","",IF(NOT(ISNUMBER(BG9)),"",IF(BG9>=5,IF(BH9<=5,"Quick win","Estructural"),IF(BH9<=5,"Mejora marginal","Descartar / replantear")))) | BJ9: =IF($E9="","",IF($B9="Nuevo",IF(NOT(ISNUMBER(BF9)),"",IF(BF9>=6,"Alta",IF(BF9>=4,"Media","Baja"))),IF($B9="En curso",IF(NOT(ISNUMBER(AV9)),"",IF(AV9>=7,"Saludable",IF(AV9>=5,"A revisar","Crítico"))),""))) | BK9: La consultoría está centralizada en el sector e incluye consultas de impuestos indirectos (~14 gerentes). El reservorio intentado alcanzó ~7 consultas cargadas: no prendió el hábito de buscar antes de trabajar y una carpeta en Teams no resuelve la búsqueda. Caso claro de 'se construyó y no se usa'. PENDIENTE: volumen de consultas por año, horas por consulta y reparto por seniority.
A10: 7 | B10: Nuevo | C10: De área | D10: Business Tax | E10: CM05 — DJ anual de Ingresos Brutos | F10: (champion de Business Tax) | G10: Declaración anual de Convenio Multilateral que resume las 12 declaraciones mensuales ya presentadas por la compañía. | H10: Interno | I10: Anual | J10: 1 | N10: =IF($E10="","",J10*K10*L10*M10) -> 0 | S10: =IF($E10="","",O10+P10+Q10+R10) -> 0 | T10: =IF($E10="","",Q10+R10) -> 0 | U10: =IF($E10="","",IFERROR(ROUND((O10*[1]Parámetros!$B$29+P10*[1]Parámetros!$B$30+Q10*[1]Parámetros!$B$31+R10*[1]Parámetros!$B$32)/S10,2),"")) | V10: =IF($E10="","",IF(O10>0,1,0)+IF(P10>0,1,0)+IF(Q10>0,1,0)+IF(R10>0,1,0)) -> 0 | AA10: Compilación entre Excel y otras herramientas | AB10: Proveedor externo (Ambitium) / Excel | AE10: 0 | AM10: =IF($B10<>"En curso","",IFERROR(AL10/AK10,"")) | AO10: =IF($B10<>"En curso","",IFERROR((AN10-L10)/AN10,"")) | AP10: =IF($B10<>"En curso","",IFERROR((AN10-L10)*J10*K10*M10,"")) | AV10: =IF($B10<>"En curso","",IF(COUNT(AK10:AL10)+COUNT(AN10)+COUNT(AQ10:AR10)=0,"",ROUND(IFERROR(N(AM10),0)*10*[1]Parámetros!$B$18+MAX(0,IFERROR(N(AO10),0))*10*[1]Parámetros!$B$19+MAX(0,1-IFERROR(N(AQ10),0)-IFERROR(N(AR10),0))*10*[1]Parámetros!$B$20+IFERROR(N(AS10),0)/4*10*[1]Parámetros!$B$21+IFERROR(N(AU10),0)/5*10*[1]Parámetros!$B$22,2))) | AW10: 4 | AX10: Workflow | AY10: Python | AZ10: 3 | BC10: =IF($B10<>"Nuevo","",IFERROR(N10*BB10,"")) -> 0 | BE10: Acceso a las 12 DDJJ mensuales presentadas; revisar el contrato con el proveedor actual. | BF10: =IF($B10<>"Nuevo","",IF(N(N10)=0,"",ROUND(MAX(0,MIN(10,MAX(0,IFERROR(N(N10)/MAX($N$4:$N$58),0)*10*[1]Parámetros!$B$5+IFERROR(N(AW10),0)*2*[1]Parámetros!$B$6+IFERROR(N(AC10),0)*2*[1]Parámetros!$B$7+IFERROR(INDEX([1]Parámetros!$B$37:$B$48,MATCH(D10,[1]Parámetros!$A$37:$A$48,0)),3)*2*[1]Parámetros!$B$8+IFERROR(N(AD10),0)*2*[1]Parámetros!$B$9+IFERROR(N(U10),0)*2.5*[1]Parámetros!$B$10+IFERROR(N(V10),0)*2.5*[1]Parámetros!$B$11+IF(Z10="Sí",10,0)*[1]Parámetros!$B$12)/[1]Parámetros!$B$14)-IFERROR(N(AZ10),0)*2*[1]Parámetros!$B$13),2))) | BG10: =IF($B10<>"Nuevo","",IF(N(N10)=0,"",ROUND(MIN(10,MAX(0,IFERROR(N(N10)/MAX($N$4:$N$58),0)*10*[1]Parámetros!$B$5+IFERROR(N(AW10),0)*2*[1]Parámetros!$B$6+IFERROR(N(AC10),0)*2*[1]Parámetros!$B$7+IFERROR(INDEX([1]Parámetros!$B$37:$B$48,MATCH(D10,[1]Parámetros!$A$37:$A$48,0)),3)*2*[1]Parámetros!$B$8+IFERROR(N(AD10),0)*2*[1]Parámetros!$B$9+IFERROR(N(U10),0)*2.5*[1]Parámetros!$B$10+IFERROR(N(V10),0)*2.5*[1]Parámetros!$B$11+IF(Z10="Sí",10,0)*[1]Parámetros!$B$12)/[1]Parámetros!$B$14),2))) | BH10: =IF($B10<>"Nuevo","",ROUND(IFERROR(AZ10,0)*2,2)) -> 6 | BI10: =IF($B10<>"Nuevo","",IF(NOT(ISNUMBER(BG10)),"",IF(BG10>=5,IF(BH10<=5,"Quick win","Estructural"),IF(BH10<=5,"Mejora marginal","Descartar / replantear")))) | BJ10: =IF($E10="","",IF($B10="Nuevo",IF(NOT(ISNUMBER(BF10)),"",IF(BF10>=6,"Alta",IF(BF10>=4,"Media","Baja"))),IF($B10="En curso",IF(NOT(ISNUMBER(AV10)),"",IF(AV10>=7,"Saludable",IF(AV10>=5,"A revisar","Crítico"))),""))) | BK10: Hoy se terceriza en un proveedor externo que cobra por armar el resumen. Nivel de automatización 0 = automatización propia inexistente. Internalizarlo tiene un ahorro de costo directo además del ahorro de horas. PENDIENTE: costo anual del proveedor, cantidad de clientes alcanzados y vencimiento (estacionalidad).
A11: 8 | B11: Nuevo | C11: De área | D11: Business Tax | E11: Bienes Personales — responsable sustituto | F11: (champion de Business Tax) | G11: Tomar del balance el saldo final de patrimonio neto, aplicar la alícuota del 0,5% y cargar la declaración en el aplicativo. | H11: Interno | I11: Anual | J11: 1 | L11: 0.75 | M11: 1 | N11: =IF($E11="","",J11*K11*L11*M11) -> 0 | S11: =IF($E11="","",O11+P11+Q11+R11) -> 0 | T11: =IF($E11="","",Q11+R11) -> 0 | U11: =IF($E11="","",IFERROR(ROUND((O11*[1]Parámetros!$B$29+P11*[1]Parámetros!$B$30+Q11*[1]Parámetros!$B$31+R11*[1]Parámetros!$B$32)/S11,2),"")) | V11: =IF($E11="","",IF(O11>0,1,0)+IF(P11>0,1,0)+IF(Q11>0,1,0)+IF(R11>0,1,0)) -> 0 | AA11: Carga en ARCA u otros portales | AB11: Excel / aplicativo | AE11: 0 | AM11: =IF($B11<>"En curso","",IFERROR(AL11/AK11,"")) | AO11: =IF($B11<>"En curso","",IFERROR((AN11-L11)/AN11,"")) | AP11: =IF($B11<>"En curso","",IFERROR((AN11-L11)*J11*K11*M11,"")) | AV11: =IF($B11<>"En curso","",IF(COUNT(AK11:AL11)+COUNT(AN11)+COUNT(AQ11:AR11)=0,"",ROUND(IFERROR(N(AM11),0)*10*[1]Parámetros!$B$18+MAX(0,IFERROR(N(AO11),0))*10*[1]Parámetros!$B$19+MAX(0,1-IFERROR(N(AQ11),0)-IFERROR(N(AR11),0))*10*[1]Parámetros!$B$20+IFERROR(N(AS11),0)/4*10*[1]Parámetros!$B$21+IFERROR(N(AU11),0)/5*10*[1]Parámetros!$B$22,2))) | AW11: 5 | AX11: Workflow | AY11: Python | AZ11: 1 | BB11: 0.89 | BC11: =IF($B11<>"Nuevo","",IFERROR(N11*BB11,"")) -> 0 | BE11: Acceso automatizado al balance y al aplicativo de carga. | BF11: =IF($B11<>"Nuevo","",IF(N(N11)=0,"",ROUND(MAX(0,MIN(10,MAX(0,IFERROR(N(N11)/MAX($N$4:$N$58),0)*10*[1]Parámetros!$B$5+IFERROR(N(AW11),0)*2*[1]Parámetros!$B$6+IFERROR(N(AC11),0)*2*[1]Parámetros!$B$7+IFERROR(INDEX([1]Parámetros!$B$37:$B$48,MATCH(D11,[1]Parámetros!$A$37:$A$48,0)),3)*2*[1]Parámetros!$B$8+IFERROR(N(AD11),0)*2*[1]Parámetros!$B$9+IFERROR(N(U11),0)*2.5*[1]Parámetros!$B$10+IFERROR(N(V11),0)*2.5*[1]Parámetros!$B$11+IF(Z11="Sí",10,0)*[1]Parámetros!$B$12)/[1]Parámetros!$B$14)-IFERROR(N(AZ11),0)*2*[1]Parámetros!$B$13),2))) | BG11: =IF($B11<>"Nuevo","",IF(N(N11)=0,"",ROUND(MIN(10,MAX(0,IFERROR(N(N11)/MAX($N$4:$N$58),0)*10*[1]Parámetros!$B$5+IFERROR(N(AW11),0)*2*[1]Parámetros!$B$6+IFERROR(N(AC11),0)*2*[1]Parámetros!$B$7+IFERROR(INDEX([1]Parámetros!$B$37:$B$48,MATCH(D11,[1]Parámetros!$A$37:$A$48,0)),3)*2*[1]Parámetros!$B$8+IFERROR(N(AD11),0)*2*[1]Parámetros!$B$9+IFERROR(N(U11),0)*2.5*[1]Parámetros!$B$10+IFERROR(N(V11),0)*2.5*[1]Parámetros!$B$11+IF(Z11="Sí",10,0)*[1]Parámetros!$B$12)/[1]Parámetros!$B$14),2))) | BH11: =IF($B11<>"Nuevo","",ROUND(IFERROR(AZ11,0)*2,2)) -> 2 | BI11: =IF($B11<>"Nuevo","",IF(NOT(ISNUMBER(BG11)),"",IF(BG11>=5,IF(BH11<=5,"Quick win","Estructural"),IF(BH11<=5,"Mejora marginal","Descartar / replantear")))) | BJ11: =IF($E11="","",IF($B11="Nuevo",IF(NOT(ISNUMBER(BF11)),"",IF(BF11>=6,"Alta",IF(BF11>=4,"Media","Baja"))),IF($B11="En curso",IF(NOT(ISNUMBER(AV11)),"",IF(AV11>=7,"Saludable",IF(AV11>=5,"A revisar","Crítico"))),""))) | BK11: Quick win declarado por el propio sector: ~30 minutos de liquidación manual más ~15 de carga (0,75 hs en total) que podrían bajar a ~5 minutos, de ahí la reducción estimada del 89%. Sin análisis: es tomar un número y aplicar una alícuota. PENDIENTE: cantidad de clientes (multiplica el ahorro) y mes de vencimiento.
A12: 9 | B12: Nuevo | C12: De área | D12: Business Tax | E12: Régimen de información de participaciones societarias | F12: (champion de Business Tax) | G12: Informar autoridades (presidente, directores, síndicos) y apoderados con poderes legales y fiscales, a partir de la lectura de las actas de directorio. | H12: Interno | I12: Anual | J12: 1 | N12: =IF($E12="","",J12*K12*L12*M12) -> 0 | S12: =IF($E12="","",O12+P12+Q12+R12) -> 0 | T12: =IF($E12="","",Q12+R12) -> 0 | U12: =IF($E12="","",IFERROR(ROUND((O12*[1]Parámetros!$B$29+P12*[1]Parámetros!$B$30+Q12*[1]Parámetros!$B$31+R12*[1]Parámetros!$B$32)/S12,2),"")) | V12: =IF($E12="","",IF(O12>0,1,0)+IF(P12>0,1,0)+IF(Q12>0,1,0)+IF(R12>0,1,0)) -> 0 | AA12: Búsqueda de información | AB12: Actas enviadas por Legales del cliente / Excel | AE12: 0 | AM12: =IF($B12<>"En curso","",IFERROR(AL12/AK12,"")) | AO12: =IF($B12<>"En curso","",IFERROR((AN12-L12)/AN12,"")) | AP12: =IF($B12<>"En curso","",IFERROR((AN12-L12)*J12*K12*M12,"")) | AV12: =IF($B12<>"En curso","",IF(COUNT(AK12:AL12)+COUNT(AN12)+COUNT(AQ12:AR12)=0,"",ROUND(IFERROR(N(AM12),0)*10*[1]Parámetros!$B$18+MAX(0,IFERROR(N(AO12),0))*10*[1]Parámetros!$B$19+MAX(0,1-IFERROR(N(AQ12),0)-IFERROR(N(AR12),0))*10*[1]Parámetros!$B$20+IFERROR(N(AS12),0)/4*10*[1]Parámetros!$B$21+IFERROR(N(AU12),0)/5*10*[1]Parámetros!$B$22,2))) | AW12: 3 | AX12: Workflow + Agente | AY12: Python + Agentes de IA | AZ12: 3 | BC12: =IF($B12<>"Nuevo","",IFERROR(N12*BB12,"")) -> 0 | BE12: Aprobación para el uso de agentes de IA; actas en formato digital legible; modelo de altas y bajas contra lo informado el año anterior. | BF12: =IF($B12<>"Nuevo","",IF(N(N12)=0,"",ROUND(MAX(0,MIN(10,MAX(0,IFERROR(N(N12)/MAX($N$4:$N$58),0)*10*[1]Parámetros!$B$5+IFERROR(N(AW12),0)*2*[1]Parámetros!$B$6+IFERROR(N(AC12),0)*2*[1]Parámetros!$B$7+IFERROR(INDEX([1]Parámetros!$B$37:$B$48,MATCH(D12,[1]Parámetros!$A$37:$A$48,0)),3)*2*[1]Parámetros!$B$8+IFERROR(N(AD12),0)*2*[1]Parámetros!$B$9+IFERROR(N(U12),0)*2.5*[1]Parámetros!$B$10+IFERROR(N(V12),0)*2.5*[1]Parámetros!$B$11+IF(Z12="Sí",10,0)*[1]Parámetros!$B$12)/[1]Parámetros!$B$14)-IFERROR(N(AZ12),0)*2*[1]Parámetros!$B$13),2))) | BG12: =IF($B12<>"Nuevo","",IF(N(N12)=0,"",ROUND(MIN(10,MAX(0,IFERROR(N(N12)/MAX($N$4:$N$58),0)*10*[1]Parámetros!$B$5+IFERROR(N(AW12),0)*2*[1]Parámetros!$B$6+IFERROR(N(AC12),0)*2*[1]Parámetros!$B$7+IFERROR(INDEX([1]Parámetros!$B$37:$B$48,MATCH(D12,[1]Parámetros!$A$37:$A$48,0)),3)*2*[1]Parámetros!$B$8+IFERROR(N(AD12),0)*2*[1]Parámetros!$B$9+IFERROR(N(U12),0)*2.5*[1]Parámetros!$B$10+IFERROR(N(V12),0)*2.5*[1]Parámetros!$B$11+IF(Z12="Sí",10,0)*[1]Parámetros!$B$12)/[1]Parámetros!$B$14),2))) | BH12: =IF($B12<>"Nuevo","",ROUND(IFERROR(AZ12,0)*2,2)) -> 6 | BI12: =IF($B12<>"Nuevo","",IF(NOT(ISNUMBER(BG12)),"",IF(BG12>=5,IF(BH12<=5,"Quick win","Estructural"),IF(BH12<=5,"Mejora marginal","Descartar / replantear")))) | BJ12: =IF($E12="","",IF($B12="Nuevo",IF(NOT(ISNUMBER(BF12)),"",IF(BF12>=6,"Alta",IF(BF12>=4,"Media","Baja"))),IF($B12="En curso",IF(NOT(ISNUMBER(AV12)),"",IF(AV12>=7,"Saludable",IF(AV12>=5,"A revisar","Crítico"))),""))) | BK12: Trabajo íntegramente mecánico y sin aprendizaje para quien lo ejecuta: se parte de lo informado el año anterior y se leen todas las actas del ejercicio buscando designaciones y revocaciones. Candidato natural a extracción documental con IA, aunque requiere diseñar cómo modelar altas y bajas. PENDIENTE: duración por cliente, cantidad de clientes y volumen típico de actas.
A13: 10 | B13: Nuevo | C13: General | D13: Business Tax | E13: Facturación y reclamo de cobranzas | F13: (champion de Business Tax) | G13: Emisión de la factura al cliente y seguimiento/reclamo de comprobantes impagos, hoy a cargo de cada gerente. | H13: Interno | I13: Mensual | J13: 12 | L13: 4 | N13: =IF($E13="","",J13*K13*L13*M13) -> 0 | S13: =IF($E13="","",O13+P13+Q13+R13) -> 0 | T13: =IF($E13="","",Q13+R13) -> 0 | U13: =IF($E13="","",IFERROR(ROUND((O13*[1]Parámetros!$B$29+P13*[1]Parámetros!$B$30+Q13*[1]Parámetros!$B$31+R13*[1]Parámetros!$B$32)/S13,2),"")) | V13: =IF($E13="","",IF(O13>0,1,0)+IF(P13>0,1,0)+IF(Q13>0,1,0)+IF(R13>0,1,0)) -> 0 | AA13: Comunicación y seguimiento | AE13: 0 | AM13: =IF($B13<>"En curso","",IFERROR(AL13/AK13,"")) | AO13: =IF($B13<>"En curso","",IFERROR((AN13-L13)/AN13,"")) | AP13: =IF($B13<>"En curso","",IFERROR((AN13-L13)*J13*K13*M13,"")) | AV13: =IF($B13<>"En curso","",IF(COUNT(AK13:AL13)+COUNT(AN13)+COUNT(AQ13:AR13)=0,"",ROUND(IFERROR(N(AM13),0)*10*[1]Parámetros!$B$18+MAX(0,IFERROR(N(AO13),0))*10*[1]Parámetros!$B$19+MAX(0,1-IFERROR(N(AQ13),0)-IFERROR(N(AR13),0))*10*[1]Parámetros!$B$20+IFERROR(N(AS13),0)/4*10*[1]Parámetros!$B$21+IFERROR(N(AU13),0)/5*10*[1]Parámetros!$B$22,2))) | AW13: 4 | AX13: Workflow + Agente | AY13: Python | AZ13: 3 | BC13: =IF($B13<>"Nuevo","",IFERROR(N13*BB13,"")) -> 0 | BF13: =IF($B13<>"Nuevo","",IF(N(N13)=0,"",ROUND(MAX(0,MIN(10,MAX(0,IFERROR(N(N13)/MAX($N$4:$N$58),0)*10*[1]Parámetros!$B$5+IFERROR(N(AW13),0)*2*[1]Parámetros!$B$6+IFERROR(N(AC13),0)*2*[1]Parámetros!$B$7+IFERROR(INDEX([1]Parámetros!$B$37:$B$48,MATCH(D13,[1]Parámetros!$A$37:$A$48,0)),3)*2*[1]Parámetros!$B$8+IFERROR(N(AD13),0)*2*[1]Parámetros!$B$9+IFERROR(N(U13),0)*2.5*[1]Parámetros!$B$10+IFERROR(N(V13),0)*2.5*[1]Parámetros!$B$11+IF(Z13="Sí",10,0)*[1]Parámetros!$B$12)/[1]Parámetros!$B$14)-IFERROR(N(AZ13),0)*2*[1]Parámetros!$B$13),2))) | BG13: =IF($B13<>"Nuevo","",IF(N(N13)=0,"",ROUND(MIN(10,MAX(0,IFERROR(N(N13)/MAX($N$4:$N$58),0)*10*[1]Parámetros!$B$5+IFERROR(N(AW13),0)*2*[1]Parámetros!$B$6+IFERROR(N(AC13),0)*2*[1]Parámetros!$B$7+IFERROR(INDEX([1]Parámetros!$B$37:$B$48,MATCH(D13,[1]Parámetros!$A$37:$A$48,0)),3)*2*[1]Parámetros!$B$8+IFERROR(N(AD13),0)*2*[1]Parámetros!$B$9+IFERROR(N(U13),0)*2.5*[1]Parámetros!$B$10+IFERROR(N(V13),0)*2.5*[1]Parámetros!$B$11+IF(Z13="Sí",10,0)*[1]Parámetros!$B$12)/[1]Parámetros!$B$14),2))) | BH13: =IF($B13<>"Nuevo","",ROUND(IFERROR(AZ13,0)*2,2)) -> 6 | BI13: =IF($B13<>"Nuevo","",IF(NOT(ISNUMBER(BG13)),"",IF(BG13>=5,IF(BH13<=5,"Quick win","Estructural"),IF(BH13<=5,"Mejora marginal","Descartar / replantear")))) | BJ13: =IF($E13="","",IF($B13="Nuevo",IF(NOT(ISNUMBER(BF13)),"",IF(BF13>=6,"Alta",IF(BF13>=4,"Media","Baja"))),IF($B13="En curso",IF(NOT(ISNUMBER(AV13)),"",IF(AV13>=7,"Saludable",IF(AV13>=5,"A revisar","Crítico"))),""))) | BK13: Dolor transversal a la gerencia, planteado también por otras áreas: se estiman ~4 horas por gerente y por mes en reclamos (cargado como duración mensual). NOTA: la unidad de 'Cantidad de clientes' aquí es la cantidad de gerentes alcanzados, no clientes — definir antes de calcular horas-persona. PENDIENTE: sistemas que intervienen (facturación, cobranzas), dueño del proceso y alcance real del pedido.
A14: 11 | N14: =IF($E14="","",J14*K14*L14*M14) | S14: =IF($E14="","",O14+P14+Q14+R14) | T14: =IF($E14="","",Q14+R14) | U14: =IF($E14="","",IFERROR(ROUND((O14*[1]Parámetros!$B$29+P14*[1]Parámetros!$B$30+Q14*[1]Parámetros!$B$31+R14*[1]Parámetros!$B$32)/S14,2),"")) | V14: =IF($E14="","",IF(O14>0,1,0)+IF(P14>0,1,0)+IF(Q14>0,1,0)+IF(R14>0,1,0)) | AM14: =IF($B14<>"En curso","",IFERROR(AL14/AK14,"")) | AO14: =IF($B14<>"En curso","",IFERROR((AN14-L14)/AN14,"")) | AP14: =IF($B14<>"En curso","",IFERROR((AN14-L14)*J14*K14*M14,"")) | AV14: =IF($B14<>"En curso","",IF(COUNT(AK14:AL14)+COUNT(AN14)+COUNT(AQ14:AR14)=0,"",ROUND(IFERROR(N(AM14),0)*10*[1]Parámetros!$B$18+MAX(0,IFERROR(N(AO14),0))*10*[1]Parámetros!$B$19+MAX(0,1-IFERROR(N(AQ14),0)-IFERROR(N(AR14),0))*10*[1]Parámetros!$B$20+IFERROR(N(AS14),0)/4*10*[1]Parámetros!$B$21+IFERROR(N(AU14),0)/5*10*[1]Parámetros!$B$22,2))) | BC14: =IF($B14<>"Nuevo","",IFERROR(N14*BB14,"")) | BF14: =IF($B14<>"Nuevo","",IF(N(N14)=0,"",ROUND(MAX(0,MIN(10,MAX(0,IFERROR(N(N14)/MAX($N$4:$N$58),0)*10*[1]Parámetros!$B$5+IFERROR(N(AW14),0)*2*[1]Parámetros!$B$6+IFERROR(N(AC14),0)*2*[1]Parámetros!$B$7+IFERROR(INDEX([1]Parámetros!$B$37:$B$48,MATCH(D14,[1]Parámetros!$A$37:$A$48,0)),3)*2*[1]Parámetros!$B$8+IFERROR(N(AD14),0)*2*[1]Parámetros!$B$9+IFERROR(N(U14),0)*2.5*[1]Parámetros!$B$10+IFERROR(N(V14),0)*2.5*[1]Parámetros!$B$11+IF(Z14="Sí",10,0)*[1]Parámetros!$B$12)/[1]Parámetros!$B$14)-IFERROR(N(AZ14),0)*2*[1]Parámetros!$B$13),2))) | BG14: =IF($B14<>"Nuevo","",IF(N(N14)=0,"",ROUND(MIN(10,MAX(0,IFERROR(N(N14)/MAX($N$4:$N$58),0)*10*[1]Parámetros!$B$5+IFERROR(N(AW14),0)*2*[1]Parámetros!$B$6+IFERROR(N(AC14),0)*2*[1]Parámetros!$B$7+IFERROR(INDEX([1]Parámetros!$B$37:$B$48,MATCH(D14,[1]Parámetros!$A$37:$A$48,0)),3)*2*[1]Parámetros!$B$8+IFERROR(N(AD14),0)*2*[1]Parámetros!$B$9+IFERROR(N(U14),0)*2.5*[1]Parámetros!$B$10+IFERROR(N(V14),0)*2.5*[1]Parámetros!$B$11+IF(Z14="Sí",10,0)*[1]Parámetros!$B$12)/[1]Parámetros!$B$14),2))) | BH14: =IF($B14<>"Nuevo","",ROUND(IFERROR(AZ14,0)*2,2)) | BI14: =IF($B14<>"Nuevo","",IF(NOT(ISNUMBER(BG14)),"",IF(BG14>=5,IF(BH14<=5,"Quick win","Estructural"),IF(BH14<=5,"Mejora marginal","Descartar / replantear")))) | BJ14: =IF($E14="","",IF($B14="Nuevo",IF(NOT(ISNUMBER(BF14)),"",IF(BF14>=6,"Alta",IF(BF14>=4,"Media","Baja"))),IF($B14="En curso",IF(NOT(ISNUMBER(AV14)),"",IF(AV14>=7,"Saludable",IF(AV14>=5,"A revisar","Crítico"))),"")))
A15: 12 | N15: =IF($E15="","",J15*K15*L15*M15) | S15: =IF($E15="","",O15+P15+Q15+R15) | T15: =IF($E15="","",Q15+R15) | U15: =IF($E15="","",IFERROR(ROUND((O15*[1]Parámetros!$B$29+P15*[1]Parámetros!$B$30+Q15*[1]Parámetros!$B$31+R15*[1]Parámetros!$B$32)/S15,2),"")) | V15: =IF($E15="","",IF(O15>0,1,0)+IF(P15>0,1,0)+IF(Q15>0,1,0)+IF(R15>0,1,0)) | AM15: =IF($B15<>"En curso","",IFERROR(AL15/AK15,"")) | AO15: =IF($B15<>"En curso","",IFERROR((AN15-L15)/AN15,"")) | AP15: =IF($B15<>"En curso","",IFERROR((AN15-L15)*J15*K15*M15,"")) | AV15: =IF($B15<>"En curso","",IF(COUNT(AK15:AL15)+COUNT(AN15)+COUNT(AQ15:AR15)=0,"",ROUND(IFERROR(N(AM15),0)*10*[1]Parámetros!$B$18+MAX(0,IFERROR(N(AO15),0))*10*[1]Parámetros!$B$19+MAX(0,1-IFERROR(N(AQ15),0)-IFERROR(N(AR15),0))*10*[1]Parámetros!$B$20+IFERROR(N(AS15),0)/4*10*[1]Parámetros!$B$21+IFERROR(N(AU15),0)/5*10*[1]Parámetros!$B$22,2))) | BC15: =IF($B15<>"Nuevo","",IFERROR(N15*BB15,"")) | BF15: =IF($B15<>"Nuevo","",IF(N(N15)=0,"",ROUND(MAX(0,MIN(10,MAX(0,IFERROR(N(N15)/MAX($N$4:$N$58),0)*10*[1]Parámetros!$B$5+IFERROR(N(AW15),0)*2*[1]Parámetros!$B$6+IFERROR(N(AC15),0)*2*[1]Parámetros!$B$7+IFERROR(INDEX([1]Parámetros!$B$37:$B$48,MATCH(D15,[1]Parámetros!$A$37:$A$48,0)),3)*2*[1]Parámetros!$B$8+IFERROR(N(AD15),0)*2*[1]Parámetros!$B$9+IFERROR(N(U15),0)*2.5*[1]Parámetros!$B$10+IFERROR(N(V15),0)*2.5*[1]Parámetros!$B$11+IF(Z15="Sí",10,0)*[1]Parámetros!$B$12)/[1]Parámetros!$B$14)-IFERROR(N(AZ15),0)*2*[1]Parámetros!$B$13),2))) | BG15: =IF($B15<>"Nuevo","",IF(N(N15)=0,"",ROUND(MIN(10,MAX(0,IFERROR(N(N15)/MAX($N$4:$N$58),0)*10*[1]Parámetros!$B$5+IFERROR(N(AW15),0)*2*[1]Parámetros!$B$6+IFERROR(N(AC15),0)*2*[1]Parámetros!$B$7+IFERROR(INDEX([1]Parámetros!$B$37:$B$48,MATCH(D15,[1]Parámetros!$A$37:$A$48,0)),3)*2*[1]Parámetros!$B$8+IFERROR(N(AD15),0)*2*[1]Parámetros!$B$9+IFERROR(N(U15),0)*2.5*[1]Parámetros!$B$10+IFERROR(N(V15),0)*2.5*[1]Parámetros!$B$11+IF(Z15="Sí",10,0)*[1]Parámetros!$B$12)/[1]Parámetros!$B$14),2))) | BH15: =IF($B15<>"Nuevo","",ROUND(IFERROR(AZ15,0)*2,2)) | BI15: =IF($B15<>"Nuevo","",IF(NOT(ISNUMBER(BG15)),"",IF(BG15>=5,IF(BH15<=5,"Quick win","Estructural"),IF(BH15<=5,"Mejora marginal","Descartar / replantear")))) | BJ15: =IF($E15="","",IF($B15="Nuevo",IF(NOT(ISNUMBER(BF15)),"",IF(BF15>=6,"Alta",IF(BF15>=4,"Media","Baja"))),IF($B15="En curso",IF(NOT(ISNUMBER(AV15)),"",IF(AV15>=7,"Saludable",IF(AV15>=5,"A revisar","Crítico"))),"")))
A16: 13 | N16: =IF($E16="","",J16*K16*L16*M16) | S16: =IF($E16="","",O16+P16+Q16+R16) | T16: =IF($E16="","",Q16+R16) | U16: =IF($E16="","",IFERROR(ROUND((O16*[1]Parámetros!$B$29+P16*[1]Parámetros!$B$30+Q16*[1]Parámetros!$B$31+R16*[1]Parámetros!$B$32)/S16,2),"")) | V16: =IF($E16="","",IF(O16>0,1,0)+IF(P16>0,1,0)+IF(Q16>0,1,0)+IF(R16>0,1,0)) | AM16: =IF($B16<>"En curso","",IFERROR(AL16/AK16,"")) | AO16: =IF($B16<>"En curso","",IFERROR((AN16-L16)/AN16,"")) | AP16: =IF($B16<>"En curso","",IFERROR((AN16-L16)*J16*K16*M16,"")) | AV16: =IF($B16<>"En curso","",IF(COUNT(AK16:AL16)+COUNT(AN16)+COUNT(AQ16:AR16)=0,"",ROUND(IFERROR(N(AM16),0)*10*[1]Parámetros!$B$18+MAX(0,IFERROR(N(AO16),0))*10*[1]Parámetros!$B$19+MAX(0,1-IFERROR(N(AQ16),0)-IFERROR(N(AR16),0))*10*[1]Parámetros!$B$20+IFERROR(N(AS16),0)/4*10*[1]Parámetros!$B$21+IFERROR(N(AU16),0)/5*10*[1]Parámetros!$B$22,2))) | BC16: =IF($B16<>"Nuevo","",IFERROR(N16*BB16,"")) | BF16: =IF($B16<>"Nuevo","",IF(N(N16)=0,"",ROUND(MAX(0,MIN(10,MAX(0,IFERROR(N(N16)/MAX($N$4:$N$58),0)*10*[1]Parámetros!$B$5+IFERROR(N(AW16),0)*2*[1]Parámetros!$B$6+IFERROR(N(AC16),0)*2*[1]Parámetros!$B$7+IFERROR(INDEX([1]Parámetros!$B$37:$B$48,MATCH(D16,[1]Parámetros!$A$37:$A$48,0)),3)*2*[1]Parámetros!$B$8+IFERROR(N(AD16),0)*2*[1]Parámetros!$B$9+IFERROR(N(U16),0)*2.5*[1]Parámetros!$B$10+IFERROR(N(V16),0)*2.5*[1]Parámetros!$B$11+IF(Z16="Sí",10,0)*[1]Parámetros!$B$12)/[1]Parámetros!$B$14)-IFERROR(N(AZ16),0)*2*[1]Parámetros!$B$13),2))) | BG16: =IF($B16<>"Nuevo","",IF(N(N16)=0,"",ROUND(MIN(10,MAX(0,IFERROR(N(N16)/MAX($N$4:$N$58),0)*10*[1]Parámetros!$B$5+IFERROR(N(AW16),0)*2*[1]Parámetros!$B$6+IFERROR(N(AC16),0)*2*[1]Parámetros!$B$7+IFERROR(INDEX([1]Parámetros!$B$37:$B$48,MATCH(D16,[1]Parámetros!$A$37:$A$48,0)),3)*2*[1]Parámetros!$B$8+IFERROR(N(AD16),0)*2*[1]Parámetros!$B$9+IFERROR(N(U16),0)*2.5*[1]Parámetros!$B$10+IFERROR(N(V16),0)*2.5*[1]Parámetros!$B$11+IF(Z16="Sí",10,0)*[1]Parámetros!$B$12)/[1]Parámetros!$B$14),2))) | BH16: =IF($B16<>"Nuevo","",ROUND(IFERROR(AZ16,0)*2,2)) | BI16: =IF($B16<>"Nuevo","",IF(NOT(ISNUMBER(BG16)),"",IF(BG16>=5,IF(BH16<=5,"Quick win","Estructural"),IF(BH16<=5,"Mejora marginal","Descartar / replantear")))) | BJ16: =IF($E16="","",IF($B16="Nuevo",IF(NOT(ISNUMBER(BF16)),"",IF(BF16>=6,"Alta",IF(BF16>=4,"Media","Baja"))),IF($B16="En curso",IF(NOT(ISNUMBER(AV16)),"",IF(AV16>=7,"Saludable",IF(AV16>=5,"A revisar","Crítico"))),"")))
A17: 14 | N17: =IF($E17="","",J17*K17*L17*M17) | S17: =IF($E17="","",O17+P17+Q17+R17) | T17: =IF($E17="","",Q17+R17) | U17: =IF($E17="","",IFERROR(ROUND((O17*[1]Parámetros!$B$29+P17*[1]Parámetros!$B$30+Q17*[1]Parámetros!$B$31+R17*[1]Parámetros!$B$32)/S17,2),"")) | V17: =IF($E17="","",IF(O17>0,1,0)+IF(P17>0,1,0)+IF(Q17>0,1,0)+IF(R17>0,1,0)) | AM17: =IF($B17<>"En curso","",IFERROR(AL17/AK17,"")) | AO17: =IF($B17<>"En curso","",IFERROR((AN17-L17)/AN17,"")) | AP17: =IF($B17<>"En curso","",IFERROR((AN17-L17)*J17*K17*M17,"")) | AV17: =IF($B17<>"En curso","",IF(COUNT(AK17:AL17)+COUNT(AN17)+COUNT(AQ17:AR17)=0,"",ROUND(IFERROR(N(AM17),0)*10*[1]Parámetros!$B$18+MAX(0,IFERROR(N(AO17),0))*10*[1]Parámetros!$B$19+MAX(0,1-IFERROR(N(AQ17),0)-IFERROR(N(AR17),0))*10*[1]Parámetros!$B$20+IFERROR(N(AS17),0)/4*10*[1]Parámetros!$B$21+IFERROR(N(AU17),0)/5*10*[1]Parámetros!$B$22,2))) | BC17: =IF($B17<>"Nuevo","",IFERROR(N17*BB17,"")) | BF17: =IF($B17<>"Nuevo","",IF(N(N17)=0,"",ROUND(MAX(0,MIN(10,MAX(0,IFERROR(N(N17)/MAX($N$4:$N$58),0)*10*[1]Parámetros!$B$5+IFERROR(N(AW17),0)*2*[1]Parámetros!$B$6+IFERROR(N(AC17),0)*2*[1]Parámetros!$B$7+IFERROR(INDEX([1]Parámetros!$B$37:$B$48,MATCH(D17,[1]Parámetros!$A$37:$A$48,0)),3)*2*[1]Parámetros!$B$8+IFERROR(N(AD17),0)*2*[1]Parámetros!$B$9+IFERROR(N(U17),0)*2.5*[1]Parámetros!$B$10+IFERROR(N(V17),0)*2.5*[1]Parámetros!$B$11+IF(Z17="Sí",10,0)*[1]Parámetros!$B$12)/[1]Parámetros!$B$14)-IFERROR(N(AZ17),0)*2*[1]Parámetros!$B$13),2))) | BG17: =IF($B17<>"Nuevo","",IF(N(N17)=0,"",ROUND(MIN(10,MAX(0,IFERROR(N(N17)/MAX($N$4:$N$58),0)*10*[1]Parámetros!$B$5+IFERROR(N(AW17),0)*2*[1]Parámetros!$B$6+IFERROR(N(AC17),0)*2*[1]Parámetros!$B$7+IFERROR(INDEX([1]Parámetros!$B$37:$B$48,MATCH(D17,[1]Parámetros!$A$37:$A$48,0)),3)*2*[1]Parámetros!$B$8+IFERROR(N(AD17),0)*2*[1]Parámetros!$B$9+IFERROR(N(U17),0)*2.5*[1]Parámetros!$B$10+IFERROR(N(V17),0)*2.5*[1]Parámetros!$B$11+IF(Z17="Sí",10,0)*[1]Parámetros!$B$12)/[1]Parámetros!$B$14),2))) | BH17: =IF($B17<>"Nuevo","",ROUND(IFERROR(AZ17,0)*2,2)) | BI17: =IF($B17<>"Nuevo","",IF(NOT(ISNUMBER(BG17)),"",IF(BG17>=5,IF(BH17<=5,"Quick win","Estructural"),IF(BH17<=5,"Mejora marginal","Descartar / replantear")))) | BJ17: =IF($E17="","",IF($B17="Nuevo",IF(NOT(ISNUMBER(BF17)),"",IF(BF17>=6,"Alta",IF(BF17>=4,"Media","Baja"))),IF($B17="En curso",IF(NOT(ISNUMBER(AV17)),"",IF(AV17>=7,"Saludable",IF(AV17>=5,"A revisar","Crítico"))),"")))
A18: 15 | N18: =IF($E18="","",J18*K18*L18*M18) | S18: =IF($E18="","",O18+P18+Q18+R18) | T18: =IF($E18="","",Q18+R18) | U18: =IF($E18="","",IFERROR(ROUND((O18*[1]Parámetros!$B$29+P18*[1]Parámetros!$B$30+Q18*[1]Parámetros!$B$31+R18*[1]Parámetros!$B$32)/S18,2),"")) | V18: =IF($E18="","",IF(O18>0,1,0)+IF(P18>0,1,0)+IF(Q18>0,1,0)+IF(R18>0,1,0)) | AM18: =IF($B18<>"En curso","",IFERROR(AL18/AK18,"")) | AO18: =IF($B18<>"En curso","",IFERROR((AN18-L18)/AN18,"")) | AP18: =IF($B18<>"En curso","",IFERROR((AN18-L18)*J18*K18*M18,"")) | AV18: =IF($B18<>"En curso","",IF(COUNT(AK18:AL18)+COUNT(AN18)+COUNT(AQ18:AR18)=0,"",ROUND(IFERROR(N(AM18),0)*10*[1]Parámetros!$B$18+MAX(0,IFERROR(N(AO18),0))*10*[1]Parámetros!$B$19+MAX(0,1-IFERROR(N(AQ18),0)-IFERROR(N(AR18),0))*10*[1]Parámetros!$B$20+IFERROR(N(AS18),0)/4*10*[1]Parámetros!$B$21+IFERROR(N(AU18),0)/5*10*[1]Parámetros!$B$22,2))) | BC18: =IF($B18<>"Nuevo","",IFERROR(N18*BB18,"")) | BF18: =IF($B18<>"Nuevo","",IF(N(N18)=0,"",ROUND(MAX(0,MIN(10,MAX(0,IFERROR(N(N18)/MAX($N$4:$N$58),0)*10*[1]Parámetros!$B$5+IFERROR(N(AW18),0)*2*[1]Parámetros!$B$6+IFERROR(N(AC18),0)*2*[1]Parámetros!$B$7+IFERROR(INDEX([1]Parámetros!$B$37:$B$48,MATCH(D18,[1]Parámetros!$A$37:$A$48,0)),3)*2*[1]Parámetros!$B$8+IFERROR(N(AD18),0)*2*[1]Parámetros!$B$9+IFERROR(N(U18),0)*2.5*[1]Parámetros!$B$10+IFERROR(N(V18),0)*2.5*[1]Parámetros!$B$11+IF(Z18="Sí",10,0)*[1]Parámetros!$B$12)/[1]Parámetros!$B$14)-IFERROR(N(AZ18),0)*2*[1]Parámetros!$B$13),2))) | BG18: =IF($B18<>"Nuevo","",IF(N(N18)=0,"",ROUND(MIN(10,MAX(0,IFERROR(N(N18)/MAX($N$4:$N$58),0)*10*[1]Parámetros!$B$5+IFERROR(N(AW18),0)*2*[1]Parámetros!$B$6+IFERROR(N(AC18),0)*2*[1]Parámetros!$B$7+IFERROR(INDEX([1]Parámetros!$B$37:$B$48,MATCH(D18,[1]Parámetros!$A$37:$A$48,0)),3)*2*[1]Parámetros!$B$8+IFERROR(N(AD18),0)*2*[1]Parámetros!$B$9+IFERROR(N(U18),0)*2.5*[1]Parámetros!$B$10+IFERROR(N(V18),0)*2.5*[1]Parámetros!$B$11+IF(Z18="Sí",10,0)*[1]Parámetros!$B$12)/[1]Parámetros!$B$14),2))) | BH18: =IF($B18<>"Nuevo","",ROUND(IFERROR(AZ18,0)*2,2)) | BI18: =IF($B18<>"Nuevo","",IF(NOT(ISNUMBER(BG18)),"",IF(BG18>=5,IF(BH18<=5,"Quick win","Estructural"),IF(BH18<=5,"Mejora marginal","Descartar / replantear")))) | BJ18: =IF($E18="","",IF($B18="Nuevo",IF(NOT(ISNUMBER(BF18)),"",IF(BF18>=6,"Alta",IF(BF18>=4,"Media","Baja"))),IF($B18="En curso",IF(NOT(ISNUMBER(AV18)),"",IF(AV18>=7,"Saludable",IF(AV18>=5,"A revisar","Crítico"))),"")))
A19: 16 | N19: =IF($E19="","",J19*K19*L19*M19) | S19: =IF($E19="","",O19+P19+Q19+R19) | T19: =IF($E19="","",Q19+R19) | U19: =IF($E19="","",IFERROR(ROUND((O19*[1]Parámetros!$B$29+P19*[1]Parámetros!$B$30+Q19*[1]Parámetros!$B$31+R19*[1]Parámetros!$B$32)/S19,2),"")) | V19: =IF($E19="","",IF(O19>0,1,0)+IF(P19>0,1,0)+IF(Q19>0,1,0)+IF(R19>0,1,0)) | AM19: =IF($B19<>"En curso","",IFERROR(AL19/AK19,"")) | AO19: =IF($B19<>"En curso","",IFERROR((AN19-L19)/AN19,"")) | AP19: =IF($B19<>"En curso","",IFERROR((AN19-L19)*J19*K19*M19,"")) | AV19: =IF($B19<>"En curso","",IF(COUNT(AK19:AL19)+COUNT(AN19)+COUNT(AQ19:AR19)=0,"",ROUND(IFERROR(N(AM19),0)*10*[1]Parámetros!$B$18+MAX(0,IFERROR(N(AO19),0))*10*[1]Parámetros!$B$19+MAX(0,1-IFERROR(N(AQ19),0)-IFERROR(N(AR19),0))*10*[1]Parámetros!$B$20+IFERROR(N(AS19),0)/4*10*[1]Parámetros!$B$21+IFERROR(N(AU19),0)/5*10*[1]Parámetros!$B$22,2))) | BC19: =IF($B19<>"Nuevo","",IFERROR(N19*BB19,"")) | BF19: =IF($B19<>"Nuevo","",IF(N(N19)=0,"",ROUND(MAX(0,MIN(10,MAX(0,IFERROR(N(N19)/MAX($N$4:$N$58),0)*10*[1]Parámetros!$B$5+IFERROR(N(AW19),0)*2*[1]Parámetros!$B$6+IFERROR(N(AC19),0)*2*[1]Parámetros!$B$7+IFERROR(INDEX([1]Parámetros!$B$37:$B$48,MATCH(D19,[1]Parámetros!$A$37:$A$48,0)),3)*2*[1]Parámetros!$B$8+IFERROR(N(AD19),0)*2*[1]Parámetros!$B$9+IFERROR(N(U19),0)*2.5*[1]Parámetros!$B$10+IFERROR(N(V19),0)*2.5*[1]Parámetros!$B$11+IF(Z19="Sí",10,0)*[1]Parámetros!$B$12)/[1]Parámetros!$B$14)-IFERROR(N(AZ19),0)*2*[1]Parámetros!$B$13),2))) | BG19: =IF($B19<>"Nuevo","",IF(N(N19)=0,"",ROUND(MIN(10,MAX(0,IFERROR(N(N19)/MAX($N$4:$N$58),0)*10*[1]Parámetros!$B$5+IFERROR(N(AW19),0)*2*[1]Parámetros!$B$6+IFERROR(N(AC19),0)*2*[1]Parámetros!$B$7+IFERROR(INDEX([1]Parámetros!$B$37:$B$48,MATCH(D19,[1]Parámetros!$A$37:$A$48,0)),3)*2*[1]Parámetros!$B$8+IFERROR(N(AD19),0)*2*[1]Parámetros!$B$9+IFERROR(N(U19),0)*2.5*[1]Parámetros!$B$10+IFERROR(N(V19),0)*2.5*[1]Parámetros!$B$11+IF(Z19="Sí",10,0)*[1]Parámetros!$B$12)/[1]Parámetros!$B$14),2))) | BH19: =IF($B19<>"Nuevo","",ROUND(IFERROR(AZ19,0)*2,2)) | BI19: =IF($B19<>"Nuevo","",IF(NOT(ISNUMBER(BG19)),"",IF(BG19>=5,IF(BH19<=5,"Quick win","Estructural"),IF(BH19<=5,"Mejora marginal","Descartar / replantear")))) | BJ19: =IF($E19="","",IF($B19="Nuevo",IF(NOT(ISNUMBER(BF19)),"",IF(BF19>=6,"Alta",IF(BF19>=4,"Media","Baja"))),IF($B19="En curso",IF(NOT(ISNUMBER(AV19)),"",IF(AV19>=7,"Saludable",IF(AV19>=5,"A revisar","Crítico"))),"")))
A20: 17 | N20: =IF($E20="","",J20*K20*L20*M20) | S20: =IF($E20="","",O20+P20+Q20+R20) | T20: =IF($E20="","",Q20+R20) | U20: =IF($E20="","",IFERROR(ROUND((O20*[1]Parámetros!$B$29+P20*[1]Parámetros!$B$30+Q20*[1]Parámetros!$B$31+R20*[1]Parámetros!$B$32)/S20,2),"")) | V20: =IF($E20="","",IF(O20>0,1,0)+IF(P20>0,1,0)+IF(Q20>0,1,0)+IF(R20>0,1,0)) | AM20: =IF($B20<>"En curso","",IFERROR(AL20/AK20,"")) | AO20: =IF($B20<>"En curso","",IFERROR((AN20-L20)/AN20,"")) | AP20: =IF($B20<>"En curso","",IFERROR((AN20-L20)*J20*K20*M20,"")) | AV20: =IF($B20<>"En curso","",IF(COUNT(AK20:AL20)+COUNT(AN20)+COUNT(AQ20:AR20)=0,"",ROUND(IFERROR(N(AM20),0)*10*[1]Parámetros!$B$18+MAX(0,IFERROR(N(AO20),0))*10*[1]Parámetros!$B$19+MAX(0,1-IFERROR(N(AQ20),0)-IFERROR(N(AR20),0))*10*[1]Parámetros!$B$20+IFERROR(N(AS20),0)/4*10*[1]Parámetros!$B$21+IFERROR(N(AU20),0)/5*10*[1]Parámetros!$B$22,2))) | BC20: =IF($B20<>"Nuevo","",IFERROR(N20*BB20,"")) | BF20: =IF($B20<>"Nuevo","",IF(N(N20)=0,"",ROUND(MAX(0,MIN(10,MAX(0,IFERROR(N(N20)/MAX($N$4:$N$58),0)*10*[1]Parámetros!$B$5+IFERROR(N(AW20),0)*2*[1]Parámetros!$B$6+IFERROR(N(AC20),0)*2*[1]Parámetros!$B$7+IFERROR(INDEX([1]Parámetros!$B$37:$B$48,MATCH(D20,[1]Parámetros!$A$37:$A$48,0)),3)*2*[1]Parámetros!$B$8+IFERROR(N(AD20),0)*2*[1]Parámetros!$B$9+IFERROR(N(U20),0)*2.5*[1]Parámetros!$B$10+IFERROR(N(V20),0)*2.5*[1]Parámetros!$B$11+IF(Z20="Sí",10,0)*[1]Parámetros!$B$12)/[1]Parámetros!$B$14)-IFERROR(N(AZ20),0)*2*[1]Parámetros!$B$13),2))) | BG20: =IF($B20<>"Nuevo","",IF(N(N20)=0,"",ROUND(MIN(10,MAX(0,IFERROR(N(N20)/MAX($N$4:$N$58),0)*10*[1]Parámetros!$B$5+IFERROR(N(AW20),0)*2*[1]Parámetros!$B$6+IFERROR(N(AC20),0)*2*[1]Parámetros!$B$7+IFERROR(INDEX([1]Parámetros!$B$37:$B$48,MATCH(D20,[1]Parámetros!$A$37:$A$48,0)),3)*2*[1]Parámetros!$B$8+IFERROR(N(AD20),0)*2*[1]Parámetros!$B$9+IFERROR(N(U20),0)*2.5*[1]Parámetros!$B$10+IFERROR(N(V20),0)*2.5*[1]Parámetros!$B$11+IF(Z20="Sí",10,0)*[1]Parámetros!$B$12)/[1]Parámetros!$B$14),2))) | BH20: =IF($B20<>"Nuevo","",ROUND(IFERROR(AZ20,0)*2,2)) | BI20: =IF($B20<>"Nuevo","",IF(NOT(ISNUMBER(BG20)),"",IF(BG20>=5,IF(BH20<=5,"Quick win","Estructural"),IF(BH20<=5,"Mejora marginal","Descartar / replantear")))) | BJ20: =IF($E20="","",IF($B20="Nuevo",IF(NOT(ISNUMBER(BF20)),"",IF(BF20>=6,"Alta",IF(BF20>=4,"Media","Baja"))),IF($B20="En curso",IF(NOT(ISNUMBER(AV20)),"",IF(AV20>=7,"Saludable",IF(AV20>=5,"A revisar","Crítico"))),"")))
A21: 18 | N21: =IF($E21="","",J21*K21*L21*M21) | S21: =IF($E21="","",O21+P21+Q21+R21) | T21: =IF($E21="","",Q21+R21) | U21: =IF($E21="","",IFERROR(ROUND((O21*[1]Parámetros!$B$29+P21*[1]Parámetros!$B$30+Q21*[1]Parámetros!$B$31+R21*[1]Parámetros!$B$32)/S21,2),"")) | V21: =IF($E21="","",IF(O21>0,1,0)+IF(P21>0,1,0)+IF(Q21>0,1,0)+IF(R21>0,1,0)) | AM21: =IF($B21<>"En curso","",IFERROR(AL21/AK21,"")) | AO21: =IF($B21<>"En curso","",IFERROR((AN21-L21)/AN21,"")) | AP21: =IF($B21<>"En curso","",IFERROR((AN21-L21)*J21*K21*M21,"")) | AV21: =IF($B21<>"En curso","",IF(COUNT(AK21:AL21)+COUNT(AN21)+COUNT(AQ21:AR21)=0,"",ROUND(IFERROR(N(AM21),0)*10*[1]Parámetros!$B$18+MAX(0,IFERROR(N(AO21),0))*10*[1]Parámetros!$B$19+MAX(0,1-IFERROR(N(AQ21),0)-IFERROR(N(AR21),0))*10*[1]Parámetros!$B$20+IFERROR(N(AS21),0)/4*10*[1]Parámetros!$B$21+IFERROR(N(AU21),0)/5*10*[1]Parámetros!$B$22,2))) | BC21: =IF($B21<>"Nuevo","",IFERROR(N21*BB21,"")) | BF21: =IF($B21<>"Nuevo","",IF(N(N21)=0,"",ROUND(MAX(0,MIN(10,MAX(0,IFERROR(N(N21)/MAX($N$4:$N$58),0)*10*[1]Parámetros!$B$5+IFERROR(N(AW21),0)*2*[1]Parámetros!$B$6+IFERROR(N(AC21),0)*2*[1]Parámetros!$B$7+IFERROR(INDEX([1]Parámetros!$B$37:$B$48,MATCH(D21,[1]Parámetros!$A$37:$A$48,0)),3)*2*[1]Parámetros!$B$8+IFERROR(N(AD21),0)*2*[1]Parámetros!$B$9+IFERROR(N(U21),0)*2.5*[1]Parámetros!$B$10+IFERROR(N(V21),0)*2.5*[1]Parámetros!$B$11+IF(Z21="Sí",10,0)*[1]Parámetros!$B$12)/[1]Parámetros!$B$14)-IFERROR(N(AZ21),0)*2*[1]Parámetros!$B$13),2))) | BG21: =IF($B21<>"Nuevo","",IF(N(N21)=0,"",ROUND(MIN(10,MAX(0,IFERROR(N(N21)/MAX($N$4:$N$58),0)*10*[1]Parámetros!$B$5+IFERROR(N(AW21),0)*2*[1]Parámetros!$B$6+IFERROR(N(AC21),0)*2*[1]Parámetros!$B$7+IFERROR(INDEX([1]Parámetros!$B$37:$B$48,MATCH(D21,[1]Parámetros!$A$37:$A$48,0)),3)*2*[1]Parámetros!$B$8+IFERROR(N(AD21),0)*2*[1]Parámetros!$B$9+IFERROR(N(U21),0)*2.5*[1]Parámetros!$B$10+IFERROR(N(V21),0)*2.5*[1]Parámetros!$B$11+IF(Z21="Sí",10,0)*[1]Parámetros!$B$12)/[1]Parámetros!$B$14),2))) | BH21: =IF($B21<>"Nuevo","",ROUND(IFERROR(AZ21,0)*2,2)) | BI21: =IF($B21<>"Nuevo","",IF(NOT(ISNUMBER(BG21)),"",IF(BG21>=5,IF(BH21<=5,"Quick win","Estructural"),IF(BH21<=5,"Mejora marginal","Descartar / replantear")))) | BJ21: =IF($E21="","",IF($B21="Nuevo",IF(NOT(ISNUMBER(BF21)),"",IF(BF21>=6,"Alta",IF(BF21>=4,"Media","Baja"))),IF($B21="En curso",IF(NOT(ISNUMBER(AV21)),"",IF(AV21>=7,"Saludable",IF(AV21>=5,"A revisar","Crítico"))),"")))
A22: 19 | N22: =IF($E22="","",J22*K22*L22*M22) | S22: =IF($E22="","",O22+P22+Q22+R22) | T22: =IF($E22="","",Q22+R22) | U22: =IF($E22="","",IFERROR(ROUND((O22*[1]Parámetros!$B$29+P22*[1]Parámetros!$B$30+Q22*[1]Parámetros!$B$31+R22*[1]Parámetros!$B$32)/S22,2),"")) | V22: =IF($E22="","",IF(O22>0,1,0)+IF(P22>0,1,0)+IF(Q22>0,1,0)+IF(R22>0,1,0)) | AM22: =IF($B22<>"En curso","",IFERROR(AL22/AK22,"")) | AO22: =IF($B22<>"En curso","",IFERROR((AN22-L22)/AN22,"")) | AP22: =IF($B22<>"En curso","",IFERROR((AN22-L22)*J22*K22*M22,"")) | AV22: =IF($B22<>"En curso","",IF(COUNT(AK22:AL22)+COUNT(AN22)+COUNT(AQ22:AR22)=0,"",ROUND(IFERROR(N(AM22),0)*10*[1]Parámetros!$B$18+MAX(0,IFERROR(N(AO22),0))*10*[1]Parámetros!$B$19+MAX(0,1-IFERROR(N(AQ22),0)-IFERROR(N(AR22),0))*10*[1]Parámetros!$B$20+IFERROR(N(AS22),0)/4*10*[1]Parámetros!$B$21+IFERROR(N(AU22),0)/5*10*[1]Parámetros!$B$22,2))) | BC22: =IF($B22<>"Nuevo","",IFERROR(N22*BB22,"")) | BF22: =IF($B22<>"Nuevo","",IF(N(N22)=0,"",ROUND(MAX(0,MIN(10,MAX(0,IFERROR(N(N22)/MAX($N$4:$N$58),0)*10*[1]Parámetros!$B$5+IFERROR(N(AW22),0)*2*[1]Parámetros!$B$6+IFERROR(N(AC22),0)*2*[1]Parámetros!$B$7+IFERROR(INDEX([1]Parámetros!$B$37:$B$48,MATCH(D22,[1]Parámetros!$A$37:$A$48,0)),3)*2*[1]Parámetros!$B$8+IFERROR(N(AD22),0)*2*[1]Parámetros!$B$9+IFERROR(N(U22),0)*2.5*[1]Parámetros!$B$10+IFERROR(N(V22),0)*2.5*[1]Parámetros!$B$11+IF(Z22="Sí",10,0)*[1]Parámetros!$B$12)/[1]Parámetros!$B$14)-IFERROR(N(AZ22),0)*2*[1]Parámetros!$B$13),2))) | BG22: =IF($B22<>"Nuevo","",IF(N(N22)=0,"",ROUND(MIN(10,MAX(0,IFERROR(N(N22)/MAX($N$4:$N$58),0)*10*[1]Parámetros!$B$5+IFERROR(N(AW22),0)*2*[1]Parámetros!$B$6+IFERROR(N(AC22),0)*2*[1]Parámetros!$B$7+IFERROR(INDEX([1]Parámetros!$B$37:$B$48,MATCH(D22,[1]Parámetros!$A$37:$A$48,0)),3)*2*[1]Parámetros!$B$8+IFERROR(N(AD22),0)*2*[1]Parámetros!$B$9+IFERROR(N(U22),0)*2.5*[1]Parámetros!$B$10+IFERROR(N(V22),0)*2.5*[1]Parámetros!$B$11+IF(Z22="Sí",10,0)*[1]Parámetros!$B$12)/[1]Parámetros!$B$14),2))) | BH22: =IF($B22<>"Nuevo","",ROUND(IFERROR(AZ22,0)*2,2)) | BI22: =IF($B22<>"Nuevo","",IF(NOT(ISNUMBER(BG22)),"",IF(BG22>=5,IF(BH22<=5,"Quick win","Estructural"),IF(BH22<=5,"Mejora marginal","Descartar / replantear")))) | BJ22: =IF($E22="","",IF($B22="Nuevo",IF(NOT(ISNUMBER(BF22)),"",IF(BF22>=6,"Alta",IF(BF22>=4,"Media","Baja"))),IF($B22="En curso",IF(NOT(ISNUMBER(AV22)),"",IF(AV22>=7,"Saludable",IF(AV22>=5,"A revisar","Crítico"))),"")))
A23: 20 | N23: =IF($E23="","",J23*K23*L23*M23) | S23: =IF($E23="","",O23+P23+Q23+R23) | T23: =IF($E23="","",Q23+R23) | U23: =IF($E23="","",IFERROR(ROUND((O23*[1]Parámetros!$B$29+P23*[1]Parámetros!$B$30+Q23*[1]Parámetros!$B$31+R23*[1]Parámetros!$B$32)/S23,2),"")) | V23: =IF($E23="","",IF(O23>0,1,0)+IF(P23>0,1,0)+IF(Q23>0,1,0)+IF(R23>0,1,0)) | AM23: =IF($B23<>"En curso","",IFERROR(AL23/AK23,"")) | AO23: =IF($B23<>"En curso","",IFERROR((AN23-L23)/AN23,"")) | AP23: =IF($B23<>"En curso","",IFERROR((AN23-L23)*J23*K23*M23,"")) | AV23: =IF($B23<>"En curso","",IF(COUNT(AK23:AL23)+COUNT(AN23)+COUNT(AQ23:AR23)=0,"",ROUND(IFERROR(N(AM23),0)*10*[1]Parámetros!$B$18+MAX(0,IFERROR(N(AO23),0))*10*[1]Parámetros!$B$19+MAX(0,1-IFERROR(N(AQ23),0)-IFERROR(N(AR23),0))*10*[1]Parámetros!$B$20+IFERROR(N(AS23),0)/4*10*[1]Parámetros!$B$21+IFERROR(N(AU23),0)/5*10*[1]Parámetros!$B$22,2))) | BC23: =IF($B23<>"Nuevo","",IFERROR(N23*BB23,"")) | BF23: =IF($B23<>"Nuevo","",IF(N(N23)=0,"",ROUND(MAX(0,MIN(10,MAX(0,IFERROR(N(N23)/MAX($N$4:$N$58),0)*10*[1]Parámetros!$B$5+IFERROR(N(AW23),0)*2*[1]Parámetros!$B$6+IFERROR(N(AC23),0)*2*[1]Parámetros!$B$7+IFERROR(INDEX([1]Parámetros!$B$37:$B$48,MATCH(D23,[1]Parámetros!$A$37:$A$48,0)),3)*2*[1]Parámetros!$B$8+IFERROR(N(AD23),0)*2*[1]Parámetros!$B$9+IFERROR(N(U23),0)*2.5*[1]Parámetros!$B$10+IFERROR(N(V23),0)*2.5*[1]Parámetros!$B$11+IF(Z23="Sí",10,0)*[1]Parámetros!$B$12)/[1]Parámetros!$B$14)-IFERROR(N(AZ23),0)*2*[1]Parámetros!$B$13),2))) | BG23: =IF($B23<>"Nuevo","",IF(N(N23)=0,"",ROUND(MIN(10,MAX(0,IFERROR(N(N23)/MAX($N$4:$N$58),0)*10*[1]Parámetros!$B$5+IFERROR(N(AW23),0)*2*[1]Parámetros!$B$6+IFERROR(N(AC23),0)*2*[1]Parámetros!$B$7+IFERROR(INDEX([1]Parámetros!$B$37:$B$48,MATCH(D23,[1]Parámetros!$A$37:$A$48,0)),3)*2*[1]Parámetros!$B$8+IFERROR(N(AD23),0)*2*[1]Parámetros!$B$9+IFERROR(N(U23),0)*2.5*[1]Parámetros!$B$10+IFERROR(N(V23),0)*2.5*[1]Parámetros!$B$11+IF(Z23="Sí",10,0)*[1]Parámetros!$B$12)/[1]Parámetros!$B$14),2))) | BH23: =IF($B23<>"Nuevo","",ROUND(IFERROR(AZ23,0)*2,2)) | BI23: =IF($B23<>"Nuevo","",IF(NOT(ISNUMBER(BG23)),"",IF(BG23>=5,IF(BH23<=5,"Quick win","Estructural"),IF(BH23<=5,"Mejora marginal","Descartar / replantear")))) | BJ23: =IF($E23="","",IF($B23="Nuevo",IF(NOT(ISNUMBER(BF23)),"",IF(BF23>=6,"Alta",IF(BF23>=4,"Media","Baja"))),IF($B23="En curso",IF(NOT(ISNUMBER(AV23)),"",IF(AV23>=7,"Saludable",IF(AV23>=5,"A revisar","Crítico"))),"")))
