Workbook

Sheet Panel BOT
B3: PANEL DE PROCESO
B4: Nombre Declaracion | C4: Procesa (SI/NO)
B5: Activo | C5: NO
B6: Pasivo | C6: NO
B7: Estado de resultados | C7: NO
B8: Patrimonio neto | C8: NO
B9: Amortizaciones aceleradas | C9: NO
B10: Resultado atribuible socios | C10: NO
B11: Distribución por tipo fuente | C11: NO
B12: Ajuste por inflación impositivo | C12: NO
B13: Ajustes - fuente argentina | C13: NO
B14: Ajustes - fuente extranjera | C14: NO
B15: Quebrantos períodos anteriores | C15: NO
... B22: Percepciones no computables | C22: NO

Sheet Datos iniciales
B1: Inicio / Datos iniciales
C2: Datos iniciales
C5: Contribuyente | D5: Dato
C6: Representando a (denominación)
C7: CUIT
C9: Datos iniciales | D9: Dato
C10: Período fiscal
C11: Secuencia | D11: Original
C12: Ejercicio (Regular / Irregular) | D12: Regular
C13: Mes de cierre | D13: 12
C14: Mes/Año de inicio del período (MM/AAAA)
C15: Establecimiento | D15: 0
C16: Empresa promovida | D16: NO
C17: Tildá las condiciones que aplican para este período (SI / NO)
C18: Tipo de rentas obtenidas | D18: SI / NO
C19: Renta de fuente argentina | D19: NO
C20: Renta de fuente extranjera | D20: NO
C21: Percibió ingresos por juegos de azar y apuestas | D21: NO
C23: Situaciones especiales | D23: SI / NO
C24: Utiliza beneficios de amortización acelerada | D24: NO
C25: Posee resultado atribuible a los socios | D25: NO
C26: Está encuadrado en una norma que admita quebrantos con tratamientos específicos, excepto venta de acciones e instrumentos financieros derivado | D26: NO
C27: Donaciones en el período | D27: NO
C29: Regímenes de promoción | D29: SI / NO
C30: Entidad exenta | D30: NO
C31: Posee estabilidad fiscal | D31: NO

Sheet Balance para fines fiscales
B1: Inicio / Nueva declaración jurada / Balance para fines fiscales
C2: Balance para fines fiscales
C3: ="PERÍODO "&'Datos iniciales'!$D$10&" | TIPO EJERCICIO "&'Datos iniciales'!$D$12&" | SECUENCIA "&'Datos iniciales'!$D$11 -> PERÍODO | TIPO EJERCICIO Regular | SECUENCIA Original
C5: Resumen del balance | D5: Según carga (web) | E5: Según balance publicado | F5: Diferencia
C6: Activo - Total activo | D6: =Activo!G9 -> 0 | F6: =IF(E6="","",D6-E6)
C7: Pasivo - Total pasivo | D7: =Pasivo!G9 -> 0 | F7: =IF(E7="","",D7-E7)
C8: Estado de resultados - Resultado final sin juegos de azar | D8: ='Estado de resultados'!G13 -> 0 | F8: =IF(E8="","",D8-E8)
C9: Estado de resultados - Resultado por juegos de azar | D9: ='Estado de resultados'!D15 -> 0 | F9: =IF(E9="","",D9-E9)
C10: Patrimonio neto - Total patrimonio neto | D10: ='Patrimonio neto'!G9 -> 0 | F10: =IF(E10="","",D10-E10)
C12: Completar "Según balance publicado" con los saldos del balance; la diferencia debe dar 0.
E13: Control Activo − Pasivo − Patrimonio neto (debe dar 0) | F13: =D6-D7-D10 -> 0

Sheet Activo
B1: Inicio / Nueva declaración jurada / Balance para fines fiscales / Activo
C2: Activo
C3: ="PERÍODO "&'Datos iniciales'!$D$10&" | TIPO EJERCICIO "&'Datos iniciales'!$D$12&" | SECUENCIA "&'Datos iniciales'!$D$11 -> PERÍODO | TIPO EJERCICIO Regular | SECUENCIA Original
C5: Caja y bancos | F5: Inversiones
C6: Créditos | F6: Bienes de uso
C7: Bienes de cambio | F7: Bienes intangibles
C9: Total activo | G9: =D5+G5+D6+G6+D7+G7 -> 0
C11: Activo corriente | F11: Activo no corriente
F13: Control corriente + no corriente (debe dar 0) | G13: =G9-D11-G11 -> 0

Sheet Pasivo
B1: Inicio / Nueva declaración jurada / Balance para fines fiscales / Pasivo
C2: Pasivo
C3: ="PERÍODO "&'Datos iniciales'!$D$10&" | TIPO EJERCICIO "&'Datos iniciales'!$D$12&" | SECUENCIA "&'Datos iniciales'!$D$11 -> PERÍODO | TIPO EJERCICIO Regular | SECUENCIA Original
C5: Deudas comerciales | F5: Deudas financieras y bancarias
C6: Sociedad controlada, controlante y vinculada | F6: Cuentas particulares de los socios
C7: Otras deudas
C9: Total pasivo | G9: =D5+G5+D6+G6+D7 -> 0
C11: Pasivo corriente | F11: Pasivo no corriente
F13: Control corriente + no corriente (debe dar 0) | G13: =G9-D11-G11 -> 0

Sheet Estado de resultados
B1: Inicio / Nueva declaración jurada / Balance para fines fiscales / Estado de resultados
C2: Estado de resultados
C3: ="PERÍODO "&'Datos iniciales'!$D$10&" | TIPO EJERCICIO "&'Datos iniciales'!$D$12&" | SECUENCIA "&'Datos iniciales'!$D$11 -> PERÍODO | TIPO EJERCICIO Regular | SECUENCIA Original
C5: Ventas, servicios y locaciones | F5: Costo total
C6: Total resultado bruto | D6: =D5-G5 -> 0
C7: Resultados financieros | F7: Cargo por deudores incobrables
C8: Otros gastos operativos | F8: Resultados extraordinarios
C9: Otros ingresos | F9: Otros egresos
C10: Resultado por ventas de acciones, cuotas, participaciones sociales | F10: Resultado por instrumentos financieros derivados
C11: Impuesto a las ganancias
C13: Resultado final del ejercicio sin juegos de azar | G13: =D6+D7-G7-D8+G8+D9-G9+D10+G10-D11 -> 0
C15: Resultado por juegos de azar
C17: Costo total, incobrables, gastos operativos, otros egresos e impuesto a las ganancias se cargan en positivo (restan).
C18: Resultados financieros, extraordinarios, venta de acciones y derivados se cargan con su signo.

Sheet Patrimonio neto
B1: Inicio / Nueva declaración jurada / Balance para fines fiscales / Patrimonio neto
C2: Patrimonio neto
C3: ="PERÍODO "&'Datos iniciales'!$D$10&" | TIPO EJERCICIO "&'Datos iniciales'!$D$12&" | SECUENCIA "&'Datos iniciales'!$D$11 -> PERÍODO | TIPO EJERCICIO Regular | SECUENCIA Original
C5: Patrimonio neto al inicio | F5: Aumentos de capital
C6: Disminuciones de capital | F6: Resultado de ejercicios anteriores
C7: Resultado final de ejercicio | D7: ='Estado de resultados'!G13 -> 0
C9: Total patrimonio neto al cierre | G9: =D5+G5-D6+G6+D7 -> 0
F11: Control Activo − Pasivo − PN (debe dar 0) | G11: =Activo!G9-Pasivo!G9-G9 -> 0

Sheet Amortizaciones aceleradas
B1: Inicio / Nueva declaración jurada / Situaciones especiales / Amortizaciones aceleradas
C2: Amortizaciones aceleradas
C3: ="PERÍODO "&'Datos iniciales'!$D$10&" | TIPO EJERCICIO "&'Datos iniciales'!$D$12&" | SECUENCIA "&'Datos iniciales'!$D$11 -> PERÍODO | TIPO EJERCICIO Regular | SECUENCIA Original
C5: Rubro | D5: Ajuste que suma al resultado de fuente argentina | E5: Ajuste que resta al resultado de fuente argentina
C6: Inmuebles | D6: =SUMIFS($E$15:$E$34,$D$15:$D$34,$C6,$E$15:$E$34,">0") -> 0 | E6: =-SUMIFS($E$15:$E$34,$D$15:$D$34,$C6,$E$15:$E$34,"<0") -> 0
C7: Rodados | D7: =SUMIFS($E$15:$E$34,$D$15:$D$34,$C7,$E$15:$E$34,">0") -> 0 | E7: =-SUMIFS($E$15:$E$34,$D$15:$D$34,$C7,$E$15:$E$34,"<0") -> 0
C8: Instalaciones | D8: =SUMIFS($E$15:$E$34,$D$15:$D$34,$C8,$E$15:$E$34,">0") -> 0 | E8: =-SUMIFS($E$15:$E$34,$D$15:$D$34,$C8,$E$15:$E$34,"<0") -> 0
C9: Bienes intangibles | D9: =SUMIFS($E$15:$E$34,$D$15:$D$34,$C9,$E$15:$E$34,">0") -> 0 | E9: =-SUMIFS($E$15:$E$34,$D$15:$D$34,$C9,$E$15:$E$34,"<0") -> 0
C10: Otros bienes de uso | D10: =SUMIFS($E$15:$E$34,$D$15:$D$34,$C10,$E$15:$E$34,">0") -> 0 | E10: =-SUMIFS($E$15:$E$34,$D$15:$D$34,$C10,$E$15:$E$34,"<0") -> 0
C11: Distribución del ajuste por amortización acelerada | D11: =SUM(D6:D10) -> 0 | E11: =SUM(E6:E10) -> 0
C13: Detalle por rubro (pantalla "Amortización acelerada <rubro>": Ley / Importe)
C14: Ley | D14: Rubro | E14: Importe
C35: Importe negativo = ajuste que resta; importe positivo = ajuste que suma (igual que en el web).

Sheet Resultado atribuible socios
B1: Inicio / Nueva declaración jurada / Situaciones especiales / Resultado atribuible a los socios
C2: Resultado atribuible a los socios
C3: ="PERÍODO "&'Datos iniciales'!$D$10&" | TIPO EJERCICIO "&'Datos iniciales'!$D$12&" | SECUENCIA "&'Datos iniciales'!$D$11 -> PERÍODO | TIPO EJERCICIO Regular | SECUENCIA Original
C4: Pantalla no incluida en el Word (figura en el módulo Situaciones especiales): se mantiene la estructura del Excel anterior.
C6: Resultado atribuible a los socios | D6: Fuente argentina | E6: Fuente extranjera
C7: Importe atribuible a los socios
C9: Detalle de socios
C10: Tipo societario | D10: CUIT/CUIL | E10: Participación % | F10: Impuesto retenido | G10: Residencia tributaria | H10: NIF | I10: Domicilio exterior | J10: País

Sheet Distribución por tipo fuente
B1: Inicio / Nueva declaración jurada / Atribución del resultado contable / Distribución del resultado por tipo de fuente
C2: Distribución de resultado por tipo de fuente
C3: ="PERÍODO "&'Datos iniciales'!$D$10&" | TIPO EJERCICIO "&'Datos iniciales'!$D$12&" | SECUENCIA "&'Datos iniciales'!$D$11 -> PERÍODO | TIPO EJERCICIO Regular | SECUENCIA Original
C5: Fuente argentina | D5: Importe
C6: Resultado final del ejercicio
C7: Resultado por venta de acciones
C8: Resultado por contratos derivados | D8: ='Estado de resultados'!G10 -> 0
C9: Total resultados con tratamientos específicos
C11: Fuente extranjera | D11: Importe
C12: Resultado final del ejercicio (apertura por país abajo) | D12: =D37 -> 0
C13: Resultado por venta de acciones
C14: Total resultados con tratamientos específicos
C16: Resultado contable de rentas de fuente argentina | D16: Importe
C17: Importe
C19: Resultado contable total | D19: Valores de referencia | E19: Totales | F19: Diferencia
C20: Resultado final del ejercicio | D20: ='Estado de resultados'!G13 -> 0 | E20: =D6+D12 -> 0 | F20: =D20-E20 -> 0
C21: Resultado por venta de acciones | D21: ='Estado de resultados'!D10 -> 0 | E21: =D7+D13 -> 0 | F21: =D21-E21 -> 0
C22: Resultado por contratos derivados | D22: ='Estado de resultados'!G10 -> 0 | E22: =D8 -> 0 | F22: =D22-E22 -> 0
C23: Resultado por tratamientos específicos | E23: =D9+D14 -> 0
C25: Resultado final del ejercicio - fuente extranjera
C26: País donde se obtuvo el resultado de fuente extranjera | D26: Resultado obtenido
C37: Resultado final del ejercicio | D37: =SUM(D27:D36) -> 0

Sheet Ajuste por inflación impositivo
B1: Inicio / Nueva declaración jurada / Ajustes al resultado / Ajuste por inflación impositivo
C2: Ajuste por inflación impositivo
C3: ="PERÍODO "&'Datos iniciales'!$D$10&" | TIPO EJERCICIO "&'Datos iniciales'!$D$12&" | SECUENCIA "&'Datos iniciales'!$D$11 -> PERÍODO | TIPO EJERCICIO Regular | SECUENCIA Original
C5: Ajuste estático | D5: Importe
C6: Activo computable
C7: Pasivo computable
C8: Capital al inicio
C9: Ajuste estático positivo
C10: Ajuste estático negativo
C12: Ajuste dinámico | D12: Importe
C13: Ajuste dinámico positivo
C14: Ajuste dinámico negativo
C16: Cargar sólo el positivo o el negativo de cada ajuste (el web inhabilita el otro).

Sheet Ajustes - fuente argentina
B1: Inicio / Nueva declaración jurada / Ajustes al resultado / Ajustes - fuente argentina
C2: Agregar ajustes - fuente argentina
C3: ="PERÍODO "&'Datos iniciales'!$D$10&" | TIPO EJERCICIO "&'Datos iniciales'!$D$12&" | SECUENCIA "&'Datos iniciales'!$D$11 -> PERÍODO | TIPO EJERCICIO Regular | SECUENCIA Original
C5: Proyecto promovido o actividad no promovida | D5: Actividad sin promoción
C7: Total ajustes - fuente argentina (pantalla "Ajustes - fuente argentina") | D7: =D22+D21 -> 0 | E7: =E22+E21 -> 0
C9: Ajustes | D9: Ajustes positivos | E9: Ajustes negativos
C10: Resultado del ajuste por inflación contable
C11: Ajuste por inflación (períodos anteriores)
C12: Ajuste estático | D12: ='Ajuste por inflación impositivo'!D9 -> 0 | E12: ='Ajuste por inflación impositivo'!D10 -> 0
C13: Ajuste dinámico | D13: ='Ajuste por inflación impositivo'!D13 -> 0 | E13: ='Ajuste por inflación impositivo'!D14 -> 0
C14: Depreciación de bienes | D14: =D31 -> 0 | E14: =E31 -> 0
C15: Diferencias de valuación | D15: =D38 -> 0 | E15: =E38 -> 0
C16: Diferencia de criterio deducibilidad por límite o tope | D16: =D47 -> 0 | E16: =E47 -> 0
C17: Diferencia de criterio procedencia de deducibilidad | D17: =D56 -> 0 | E17: =E56 -> 0
C18: Ajustes por precios de transferencia
C19: Ajuste correlativo por precio de transferencia
C20: Otros ajustes | D20: =D66 -> 0 | E20: =E66 -> 0
C21: Ajustes por venta de acciones, contratos derivados, juegos de azar y de tratamientos específicos | D21: =D73 -> 0 | E21: =E73 -> 0
C22: Subtotal de ajustes, excepto por venta de acciones, instrumentos financieros derivados y tratamientos específicos | D22: =SUM(D10:D20) -> 0 | E22: =SUM(E10:E20) -> 0
C25: Ajustes por depreciación de bienes | D25: Ajustes positivos | E25: Ajustes negativos
C26: Muebles
C27: Inmuebles
C28: Inmateriales
C29: No revisten carácter de bienes de cambio
C30: Ajuste por amortización acelerada | D30: ='Amortizaciones aceleradas'!D11 -> 0 | E30: ='Amortizaciones aceleradas'!E11 -> 0
C31: Total de ajustes por depreciación | D31: =SUM(D26:D30) -> 0 | E31: =SUM(E26:E30) -> 0
C34: Ajustes por diferencia de valuación | D34: Ajustes positivos | E34: Ajustes negativos
C35: Diferencia de valuación bienes de cambio
C36: Diferencias de valuación de acciones, cuotas partes, FCI, participación en fideicomisos y similares
C37: Otros ajustes por valuación
C38: Total de ajustes por diferencia de valuación | D38: =SUM(D35:D37) -> 0 | E38: =SUM(E35:E37) -> 0
C41: Ajustes por diferencia de criterio deducibilidad por límite o tope | D41: Ajustes positivos | E41: Ajustes negativos
C42: Gastos de mantenimiento y funcionamiento de automóviles no deducibles
C43: Intereses financieros de empresas vinculadas
C44: Honorarios directores, socios gerentes y similares
C45: Gastos de representación
C46: Otros ajustes por diferencia de criterio límite o tope
C47: Total de ajustes por diferencia de criterio deducibilidad | D47: =SUM(D42:D46) -> 0 | E47: =SUM(E42:E46) -> 0
C50: Ajustes por diferencia criterio procedencia de deducibilidad | D50: Ajustes positivos | E50: Ajustes negativos
C51: Impuestos a las ganancias
...

Sheet Ajustes - fuente extranjera
B1: Inicio / Nueva declaración jurada / Ajustes al resultado / Ajustes - fuente extranjera
C2: Agregar ajustes - fuente extranjera
C3: ="PERÍODO "&'Datos iniciales'!$D$10&" | TIPO EJERCICIO "&'Datos iniciales'!$D$12&" | SECUENCIA "&'Datos iniciales'!$D$11 -> PERÍODO | TIPO EJERCICIO Regular | SECUENCIA Original
C5: Proyecto promovido o actividad no promovida | D5: Actividad sin promoción
C7: Total ajustes - fuente extranjera (pantalla "Ajustes - fuente extranjera") | D7: =D19+D18 -> 0 | E7: =E19+E18 -> 0
C9: Ajustes | D9: Ajustes positivos | E9: Ajustes negativos
C10: Resultado del ajuste por inflación contable
C11: Depreciación de bienes | D11: =D27 -> 0 | E11: =E27 -> 0
C12: Diferencias de valuación | D12: =D34 -> 0 | E12: =E34 -> 0
C13: Diferencia de criterio deducibilidad por límite o tope | D13: =D43 -> 0 | E13: =E43 -> 0
C14: Diferencia de criterio procedencia de deducibilidad | D14: =D52 -> 0 | E14: =E52 -> 0
C15: Ajustes por precios de transferencia
C16: Ajuste correlativo por precio de transferencia
C17: Otros ajustes | D17: =D62 -> 0 | E17: =E62 -> 0
C18: Ajustes por venta de acciones, contratos derivados, juegos de azar y de tratamientos específicos | D18: =D69 -> 0 | E18: =E69 -> 0
C19: Subtotal de ajustes, excepto por venta de acciones, instrumentos financieros derivados y tratamientos específicos | D19: =SUM(D10:D17) -> 0 | E19: =SUM(E10:E17) -> 0
C22: Ajustes por depreciación de bienes | D22: Ajustes positivos | E22: Ajustes negativos
C23: Muebles
C24: Inmuebles
C25: Inmateriales
C26: No revisten carácter de bienes de cambio
C27: Total de ajustes por depreciación | D27: =SUM(D23:D26) -> 0 | E27: =SUM(E23:E26) -> 0
C30: Ajustes por diferencia de valuación | D30: Ajustes positivos | E30: Ajustes negativos
C31: Diferencia de valuación bienes de cambio
C32: Diferencias de valuación de acciones, cuotas partes, FCI, participación en fideicomisos y similares
C33: Otros ajustes por valuación
C34: Total de ajustes por diferencia de valuación | D34: =SUM(D31:D33) -> 0 | E34: =SUM(E31:E33) -> 0
C37: Ajustes por diferencia de criterio deducibilidad por límite o tope | D37: Ajustes positivos | E37: Ajustes negativos
C38: Gastos de mantenimiento y funcionamiento de automóviles no deducibles
C39: Intereses financieros de empresas vinculadas
C40: Honorarios directores, socios gerentes y similares
C41: Gastos de representación
C42: Otros ajustes por diferencia de criterio límite o tope
C43: Total de ajustes por diferencia de criterio deducibilidad | D43: =SUM(D38:D42) -> 0 | E43: =SUM(E38:E42) -> 0
C46: Ajustes por diferencia criterio procedencia de deducibilidad | D46: Ajustes positivos | E46: Ajustes negativos
C47: Impuestos a las ganancias
C48: Donaciones efectuadas
C49: Créditos incobrables
C50: Previsiones no deducibles
C51: Otros ajustes por deducción no procedente
...

Sheet Quebrantos períodos anteriores
B1: Inicio / Nueva declaración jurada / Determinación del impuesto / Quebrantos períodos anteriores
C2: Agregar quebrantos (fuente argentina / fuente extranjera)
C3: ="PERÍODO "&'Datos iniciales'!$D$10&" | TIPO EJERCICIO "&'Datos iniciales'!$D$12&" | SECUENCIA "&'Datos iniciales'!$D$11 -> PERÍODO | TIPO EJERCICIO Regular | SECUENCIA Original
C5: Fuente | D5: Actividad | E5: Período fiscal | F5: ¿Recibido por cesión Ley 27742? | G5: ¿Cedido por cesión Ley 27742? | H5: Quebranto | I5: Total | J5: Actualización | K5: Computable | L5: Trasladable
L6: =IF($H6="","",I6+J6-K6)
L7: =IF($H7="","",I7+J7-K7)
L8: =IF($H8="","",I8+J8-K8)
L9: =IF($H9="","",I9+J9-K9)
L10: =IF($H10="","",I10+J10-K10)
L11: =IF($H11="","",I11+J11-K11)
L12: =IF($H12="","",I12+J12-K12)
L13: =IF($H13="","",I13+J13-K13)
L14: =IF($H14="","",I14+J14-K14)
L15: =IF($H15="","",I15+J15-K15)
L16: =IF($H16="","",I16+J16-K16)
L17: =IF($H17="","",I17+J17-K17)
... L55: =IF($H55="","",I55+J55-K55)
C57: Una fila por período fiscal y tipo de quebranto. Actualización la calcula el web (completar para control). Trasladable = Total + Actualización − Computable.

Sheet Determinación resultado neto
B1: Inicio / Nueva declaración jurada / Determinación del impuesto / Determinación del resultado neto
C2: Determinación del resultado neto
C3: ="PERÍODO "&'Datos iniciales'!$D$10&" | TIPO EJERCICIO "&'Datos iniciales'!$D$12&" | SECUENCIA "&'Datos iniciales'!$D$11 -> PERÍODO | TIPO EJERCICIO Regular | SECUENCIA Original
C5: Actividad | D5: ='Ajustes - fuente argentina'!D5 -> Actividad sin promoción
C7: Determinación del resultado neto | D7: Fuente argentina | E7: Fuente extranjera
C8: Resultado contable | D8: ='Distribución por tipo fuente'!D6 -> 0 | E8: ='Distribución por tipo fuente'!D12 -> 0
C9: Ajustes | D9: ='Ajustes - fuente argentina'!D7-'Ajustes - fuente argentina'!E7 -> 0 | E9: ='Ajustes - fuente extranjera'!D7-'Ajustes - fuente extranjera'!E7 -> 0
C10: Resultado impositivo antes de donaciones | D10: =D8+D9 -> 0
C11: Donaciones computables | D11: =MIN('Donaciones efectuadas'!E26,MAX(0,5%*D10)) -> 0
C12: Resultado impositivo | D12: =D10-D11 -> 0 | E12: =E8+E9 -> 0
C14: Quebrantos por venta de acciones | D14: =SUMIFS('Quebrantos períodos anteriores'!$K$6:$K$55,'Quebrantos períodos anteriores'!$C$6:$C$55,"Argentina",'Quebrantos períodos anteriores'!$H$6:$H$55,"Quebranto por venta de acciones") -> 0 | E14: =SUMIFS('Quebrantos períodos anteriores'!$K$6:$K$55,'Quebrantos períodos anteriores'!$C$6:$C$55,"Extranjera",'Quebrantos períodos anteriores'!$H$6:$H$55,"Quebranto por venta de acciones") -> 0
C15: Quebrantos por instrumentos financieros derivados (fuente argentina) | D15: =SUMIFS('Quebrantos períodos anteriores'!$K$6:$K$55,'Quebrantos períodos anteriores'!$C$6:$C$55,"Argentina",'Quebrantos períodos anteriores'!$H$6:$H$55,"Por instrumentos financieros derivados") -> 0
C16: Quebrantos por tratamientos específicos | D16: =SUMIFS('Quebrantos períodos anteriores'!$K$6:$K$55,'Quebrantos períodos anteriores'!$C$6:$C$55,"Argentina",'Quebrantos períodos anteriores'!$H$6:$H$55,"Por tratamientos específicos") -> 0 | E16: =SUMIFS('Quebrantos períodos anteriores'!$K$6:$K$55,'Quebrantos períodos anteriores'!$C$6:$C$55,"Extranjera",'Quebrantos períodos anteriores'!$H$6:$H$55,"Por tratamientos específicos") -> 0
C17: Quebrantos computables | D17: =SUMIFS('Quebrantos períodos anteriores'!$K$6:$K$55,'Quebrantos períodos anteriores'!$C$6:$C$55,"Argentina",'Quebrantos períodos anteriores'!$H$6:$H$55,"Resto") -> 0 | E17: =SUMIFS('Quebrantos períodos anteriores'!$K$6:$K$55,'Quebrantos períodos anteriores'!$C$6:$C$55,"Extranjera",'Quebrantos períodos anteriores'!$H$6:$H$55,"Resto") -> 0
C19: Resultado neto | D19: =D12-SUM(D14:D17) -> 0 | E19: =E12-SUM(E14:E17) -> 0
C20: Resultado atribuible a los socios | D20: ='Resultado atribuible socios'!D7 -> 0 | E20: ='Resultado atribuible socios'!E7 -> 0
C21: Quebranto de fuente argentina (fuente extranjera)
C22: Quebranto de fuente argentina de ejercicios anteriores (fuente extranjera)
C23: Compensación de quebrantos de otras actividades
C25: Resultado neto final | D25: =D19-D20-D23 -> 0 | E25: =E19-E20-E21-E22-E23 -> 0
C26: Impuesto determinado | D26: =D36-E26 -> 0 | E26: =IF(D36=0,0,ROUND(D36*MAX(E25,0)/(MAX(D25,0)+MAX(E25,0)),2)) -> 0
C28: Resultado neto total | D28: Importe
C29: Total resultado contable | D29: =D8+E8 -> 0
C30: Total ajustes | D30: =D9+E9 -> 0
C31: Total resultado impositivo antes de donaciones (F.A.) | D31: =D10 -> 0
C32: Total donaciones computables (F.A.) | D32: =D11 -> 0
C33: Total resultado impositivo | D33: =D12+E12 -> 0
C34: Total resultado neto | D34: =D25+E25 -> 0
C35: Ganancia neta imponible acumulada | D35: =MAX(0,D34) -> 0
C36: Total impuesto determinado | D36: =ROUND(IF(D35<=0,0,IF(D35<=E40,F40+(D35-D40)*G40,IF(D35<=E41,F41+(D35-D41)*G41,F42+(D35-D42)*G42))),2) -> 0
C39: Escala art. 73 LIG para sociedades (actualizar cada período) | D39: Más de $ | E39: A $ | F39: Monto fijo $ | G39: % s/ excedente
C40: Tramo 1 | D40: 0 | E40: 1.0167958e+08 | F40: 0 | G40: 0.25
C41: Tramo 2 | D41: 1.0167958e+08 | E41: 1.0167958e+09 | F41: 25419894 | G41: 0.3
C42: Tramo 3 | D42: 1.0167958e+09 | E42: En adelante | F42: 2.9995475e+08 | G42: 0.35
C44: Escala para ejercicios iniciados desde el 01/01/2025 (con ella se obtiene el mismo impuesto que en el Word).
C45: El impuesto se calcula sobre la ganancia neta imponible acumulada y se distribuye entre F.A. y F.E. en proporción al resultado neto final.
C46: Donaciones computables: tope del 5% sobre el resultado impositivo antes de donaciones (verificar contra el web).

Sheet Donaciones efectuadas
B1: Inicio / Nueva declaración jurada / Determinación del impuesto / Donaciones efectuadas
C2: Agregar donaciones
C3: ="PERÍODO "&'Datos iniciales'!$D$10&" | TIPO EJERCICIO "&'Datos iniciales'!$D$12&" | SECUENCIA "&'Datos iniciales'!$D$11 -> PERÍODO | TIPO EJERCICIO Regular | SECUENCIA Original
C5: CUIT | D5: Denominación | E5: Importe de las donaciones del período
C26: Total donaciones efectuadas | E26: =SUM(E6:E25) -> 0
D28: Control vs. "Donaciones efectuadas" en Ajustes - fuente argentina (debe dar 0) | E28: =E26-'Ajustes - fuente argentina'!D52 -> 0

Sheet Determinación del saldo
B1: Inicio / Nueva declaración jurada / Determinación del saldo
C2: Determinación del saldo
C3: ="PERÍODO "&'Datos iniciales'!$D$10&" | TIPO EJERCICIO "&'Datos iniciales'!$D$12&" | SECUENCIA "&'Datos iniciales'!$D$11 -> PERÍODO | TIPO EJERCICIO Regular | SECUENCIA Original
C5: Determinación del saldo | D5: A favor de ARCA | E5: A favor del contribuyente
C6: Impuesto determinado fuente extranjera | D6: ='Determinación resultado neto'!E26 -> 0
C7: ¿La renta o bienes de fuente extranjera estuvieron sujetos al pago de impuestos análogos en el exterior? | D7: NO
C8: Monto total computable de los impuestos análogos pagados en el exterior
C9: Subtotal fuente extranjera | D9: =MAX(0,D6-E8) -> 0
C10: Impuesto determinado fuente argentina | D10: ='Determinación resultado neto'!D26 -> 0
C11: ¿La renta de fuente argentina estuvo sujeta al pago de impuesto análogo en países con Convenios internacionales que admiten su cómputo? | D11: NO
C12: Impuesto análogo pagado en el exterior computable contra ganancias de fuente argentina admitido por convenios internacionales
C13: Subtotal fuente argentina | D13: =MAX(0,D10-E12) -> 0
C14: Diferimiento F.518
C15: Subtotal general | D15: =MAX(0,D9+D13-E14) -> 0
C16: Saldo previo al cómputo del impuesto sobre los créditos y débitos | D16: =MAX(0,D15-SUM(E19:E23)) -> 0
C18: Pagos a cuenta | D18: A favor de ARCA | E18: A favor del contribuyente
C19: Pago a cuenta ley de promoción a la investigación
C20: Pago a cuenta impuesto sobre los combustibles líquidos
C21: Pago a cuenta compraventa de moneda extranjera
C22: Pago a cuenta fomento a las inversiones productivas Pymes - Ley 27264 (detalle al pie) | E22: =E64 -> 0
C23: Otros pagos a cuenta
C25: Cómputo del impuesto sobre los créditos y débitos | D25: A favor de ARCA | E25: A favor del contribuyente
C26: Anticipos cancelados con cómputo del impuesto sobre los créditos y débitos | E26: ='Anticipos imp créd. y débitos'!L6 -> 0
C27: Cómputo de impuesto sobre los créditos y débitos para cancelación de DDJJ | E27: ='Imp créditos y débitos'!K6 -> 0
C28: Saldo a favor del contribuyente por anticipos cancelados con impuesto sobre los créditos y débitos | E28: =MAX(0,E26-D16) -> 0
C29: Saldo a cancelar | D29: =MAX(0,D16-E26) -> 0
C30: Saldo a ingresar | D30: =MAX(0,D29-E27) -> 0
C32: Cómputo de bonos o certificados fiscales | D32: A favor de ARCA | E32: A favor del contribuyente
C33: Anticipos cancelados con cómputo de bonos y créditos fiscales
C34: Cómputo de bonos y créditos fiscales para cancelación de DDJJ
C35: Saldo a favor del contribuyente por anticipos cancelados con Bonos o Certificados Fiscales | E35: =MAX(0,E33-D30) -> 0
C36: Saldo a ingresar previo al cómputo de bonos para cancelar DDJJ | D36: =MAX(0,D30-E33) -> 0
C37: Saldo a ingresar | D37: =MAX(0,D36-E34) -> 0
C39: Anticipos abonados en efectivo o compensados en Sistema de cuentas tributarias | D39: A favor de ARCA | E39: A favor del contribuyente
C40: Anticipos cancelados en efectivo o compensación
C41: Anticipos cancelados con planes mis facilidades
C42: Total de anticipos | E42: =E40+E41 -> 0
C44: Retenciones y percepciones | D44: A favor de ARCA | E44: A favor del contribuyente
C45: Retenciones y percepciones | E45: ='Retenciones y percepciones'!O10 -> 0
C46: Percepciones no computables para el cálculo de anticipos (percepciones aduaneras) | E46: ='Percepciones no computables'!H6 -> 0
...

Sheet Anticipos imp créd. y débitos
B1: Inicio / Nueva declaración jurada / Determinación del saldo / Anticipos imp créditos y débitos
C2: Anticipos cancelados con cómputo del impuesto sobre los créditos y débitos
C3: ="PERÍODO "&'Datos iniciales'!$D$10&" | TIPO EJERCICIO "&'Datos iniciales'!$D$12&" | SECUENCIA "&'Datos iniciales'!$D$11 -> PERÍODO | TIPO EJERCICIO Regular | SECUENCIA Original
C5: Número de anticipo | D5: Importe computado | E5: Proveniente de | F5: Período de la percepción (AAAA/MM) | G5: CUIT del agente de la percepción | H5: CUIT del titular de la cuenta | I5: Tipo de cuenta | J5: Número de CBU/CVU | L5: Anticipos cancelados con imputación del impuesto sobre los créditos y débitos
L6: =SUM(D6:D5005) -> 0

Sheet Imp créditos y débitos
B1: Inicio / Nueva declaración jurada / Determinación del saldo / Imp créditos y débitos
C2: Cómputo de impuesto sobre los créditos y débitos para cancelación de DDJJ
C3: ="PERÍODO "&'Datos iniciales'!$D$10&" | TIPO EJERCICIO "&'Datos iniciales'!$D$12&" | SECUENCIA "&'Datos iniciales'!$D$11 -> PERÍODO | TIPO EJERCICIO Regular | SECUENCIA Original
C5: Importe | D5: Proveniente de | E5: Período de la percepción (AAAA/MM) | F5: CUIT del agente de la percepción | G5: CUIT del titular de la cuenta | H5: Tipo de cuenta | I5: CBU/CVU | K5: Total pago a cuenta por imputación del impuesto sobre los créditos y débitos
K6: =SUM(C6:C5005) -> 0

Sheet Retenciones y percepciones
B1: Inicio / Nueva declaración jurada / Determinación del saldo / Retenciones y percepciones
C2: Retenciones y percepciones
C3: ="PERÍODO "&'Datos iniciales'!$D$10&" | TIPO EJERCICIO "&'Datos iniciales'!$D$12&" | SECUENCIA "&'Datos iniciales'!$D$11 -> PERÍODO | TIPO EJERCICIO Regular | SECUENCIA Original
C5: CUIT del agente de retención/percepción | D5: Descripción de la operación | E5: Impuesto | F5: Régimen | G5: Fecha de retención/percepción | H5: Número de certificado | I5: Número de comprobante | J5: Fecha de comprobante | K5: Descripción comprobante | L5: Importe | N5: Totales (pantalla "Retenciones y percepciones") | O5: Importe
N6: Autorretención (total VEPs pagados)
N7: Total retenciones calculadas | O7: =SUMIF(D6:D5005,"Retención",L6:L5005) -> 0
N8: Total de retenciones (si difiere de lo calculado, reemplazar) | O8: =O7 -> 0
N9: Total de percepciones | O9: =SUMIF(D6:D5005,"Percepción",L6:L5005) -> 0
N10: Total de retenciones, percepciones y autorretenciones | O10: =O6+O8+O9 -> 0

Sheet Percepciones no computables
B1: Inicio / Nueva declaración jurada / Determinación del saldo / Percepciones no computables para el cálculo de anticipos
C2: Percepciones no computables para el cálculo de anticipos (percepciones aduaneras)
C3: ="PERÍODO "&'Datos iniciales'!$D$10&" | TIPO EJERCICIO "&'Datos iniciales'!$D$12&" | SECUENCIA "&'Datos iniciales'!$D$11 -> PERÍODO | TIPO EJERCICIO Regular | SECUENCIA Original
C4: Pantalla no incluida en el Word (se abre con el lápiz en "Retenciones y percepciones" de Determinación del saldo).
C5: Número de certificado | D5: Fecha de percepción (DD/MM/AAAA) | E5: Importe | F5: Régimen | H5: Percepciones no computables para el cálculo de anticipos
H6: =SUM(E6:E5005) -> 0

Sheet Listas
A1: SI/NO | B1: Proveniente de | C1: Ejercicio | D1: Secuencia | E1: Rubro amortización acelerada | F1: Ley amortización acelerada | G1: País | H1: Descripción de la operación | I1: Régimen percepción aduanera | J1: Residencia tributaria | K1: Mes | L1: Fuente | M1: Tipo de quebranto | N1: Proyecto
A2: SI | B2: Percepción bancaria o ingreso propio | C2: Regular | D2: Original | E2: Inmuebles | F2: Nº 24.196 Inversiones Mineras | G2: Afganistán | H2: Retención | I2: 531 Import. def. bs. para venta - art. 40 1er párrafo | J2: Local | K2: 1 | L2: Argentina | M2: Quebranto por venta de acciones | N2: Actividad sin promoción
A3: NO | B3: DDJJ | C3: Irregular | D3: Rectificativa 1 | E3: Rodados | F3: Nº 25.080 Ley de Inversiones para bosques cultivados | G3: Albania | H3: Percepción | I3: 080 Importación definitiva de bienes con C.V.D.I. | J3: Exterior | K3: 2 | L3: Extranjera | M3: Por instrumentos financieros derivados
D4: Rectificativa 2 | E4: Instalaciones | F4: Nº 25.922 Ley de Promoción de la Industria del Software | G4: Alemania | I4: 081 Importación definitiva de bienes para uso de importador con C.V.D.I. | K4: 3 | M4: Resto
D5: Rectificativa 3 | E5: Bienes intangibles | F5: Nº 25.924 Inversiones en Bienes de Capital nuevos y obras de infraestructura | G5: Anguila | I5: 082 Importación definitiva de bienes para uso de importador sin C.V.D.I. | K5: 4 | M5: Por juegos de azar
D6: Rectificativa 4 | E6: Otros bienes de uso | F6: Nº 26.093 Régimen de Regulación y Promoción para la Producción y Uso Sustentables de Biocombustibles | G6: Antártida | I6: 083 Importación definitiva de bienes sin C.V.D.I. | K6: 5 | M6: Por tratamientos específicos
D7: Rectificativa 5 | F7: Nº 26.123 Promoción del Hidrógeno | G7: Antigua y Barbuda | I7: 864 Operaciones de exportación definitiva para consumo | K7: 6
D8: Rectificativa 6 | F8: Nº 26.154 Regímenes promocionales para la exploración y explotación de hidrocarburos | G8: Antillas Holandesas / Neerlandesas | I8: 588 Ganancias. Percepcion Aduanera Metales Preciosos. RG 5815 | K8: 7
D9: Rectificativa 7 | F9: Nº 26.190 Régimen de Fomento Nacional para el uso de fuentes renovables de energía destinada a la producción de energía eléctrica | G9: Arabia Saudita | K9: 8
D10: Rectificativa 8 | F10: Nº 26.270 Promoción del desarrollo y producción de la biotecnología moderna | G10: Argelia | K10: 9
D11: Rectificativa 9 | F11: Nº 26.360 Promoción de inversiones en Bienes de Capital y Obras de Infraestructura | G11: Armenia | K11: 10
F12: N° 27.541 Ley de Solidaridad Social - Beneficio cumplidores | G12: Aruba | K12: 11
F13: N° 27.653 Ley de Alivio Fiscal | G13: Ascención | K13: 12
F14: N° 27.686 Ley de Promoción de Inveriones en la Ind. Automotriz y su cadena de valor | G14: Australia
F15: Otra | G15: Austria
G16: Azerbaiyán
G17: Bahamas, Islas
G18: Barbados
G19: Bélgica
G20: Belice
G21: Benín
G22: Bermudas
G23: Bielorrusia
G24: Bolivia
G25: Bosnia y Herzegovina
G26: Botswana
G27: Brasil
... G268: Zimbabwe / Zimbabue
