Workbook

Sheet Anexo II
C2: LEY N°. 987 – LEY DE REFORMAS Y ADICIONES A LA LEY N°. 822, LEY DE CONCERTACIÓN TRIBUTARIA
C3: ANEXO II – LISTA DE BIENES DE CONSUMO GRAVADOS CON ISC, SOBRE LOS QUE NO APLICAN EXENCIONES Y EXONERACIONES
C4: La Gaceta, Diario Oficial N°. 41 del 28 de febrero de 2019
C5: A. BIENES GRAVADOS CON ISC (ALÍCUOTA AD VALOREM)
C6: CÓDIGO | D6: DESCRIPCIÓN | E6: ISC (%)
C7: 2203.00.00.00.10 | D7: - En latas | E7: 36
C8: 2203.00.00.00.90 | D8: - Otros | E8: 33
C9: 2204.10.00.00.00 | D9: - Vino espumoso | E9: 37
C10: 2204.21.00.00.00 | D10: - - En recipientes con capacidad inferior o igual a 2 l | E10: 37
C11: 2204.22.00.00.00 | D11: - - En recipientes con capacidad superior a 2 l pero inferior o igual a 10 l | E11: 37
C12: 2204.29.00.00.00 | D12: - - Los demás | E12: 37
C13: 2204.30.00.00.00 | D13: - Los demás mostos de uva | E13: 15
C14: 2205.10.00.00.00 | D14: - En recipientes con capacidad inferior o igual a 2 l | E14: 37
C15: 2205.90.00.00.00 | D15: - Los demás | E15: 37
C16: 2206.00.00.00.00 | D16: LAS DEMÁS BEBIDAS FERMENTADAS (POR EJEMPLO: SIDRA, PERADA, AGUAMIEL, SAKE); MEZCLAS DE BEBIDAS FERMENTADAS Y MEZCLAS DE BEBIDAS FERMENTADAS Y BEBIDAS NO ALCOHÓLICAS, NO EXPRESADAS NI COMPRENDIDAS EN OTRA PARTE | E16: 22
C17: 2207.10.10.00.00 | D17: - - Alcohol etílico absoluto | E17: 42
C18: 2207.10.90.00.90 | D18: - - - Los demás | E18: 42
... C98: 7117.90.00.00.00 | D98: - Las demás | E98: 30
C100: De conformidad con los artículos 190 y 191 de la presente Ley, la cuota del IECT que grava los siguientes incisos, se actualiza anualmente a partir del 1 de enero de cada año.
C101: B. IMPUESTO ESPECÍFICO AL CONSUMO DE CIGARRILLOS Y OTROS PRODUCTOS DE TABACO (IECT)
C102: CÓDIGO | D102: DESCRIPCIÓN | E102: CUOTA IECT (C$)
C103: 2402.10.00.00.00 | D103: - Cigarros (puros) (incluso despuntados) y cigarritos (puritos), que contengan tabaco | E103: C$1, 335. 0
C104: 2402.20.00.00.00 | D104: - Cigarrillos que contengan tabaco | E104: C$2, 000. 0
C105: 2402.90.00.00.00 | D105: - Los demás | E105: C$1, 335. 0
C106: 2403.19.10.00.00 | D106: - - - Picadura de tabaco, para hacer cigarrillos | E106: C$1, 335. 0
C108: De conformidad con el artículo 151 de la presente Ley, los siguientes incisos, adicional al ISC ad valorem antes indicado, están gravados con una cuota específica de cincuenta córdobas (C$50.00) por cada litro de alcohol; este monto se actualiza anualmente a partir del 1 de enero de cada año.
C109: C. INCISOS GRAVADOS ADICIONALMENTE CON CUOTA ESPECÍFICA DE C$50.00 POR LITRO DE ALCOHOL
C110: CÓDIGO | D110: DESCRIPCIÓN | E110: CUOTA ESPECÍFICA
C111: 2203.00.00.00.10 | D111: - En latas | E111: C$50.00/litro alcohol
C112: 2203.00.00.00.90 | D112: - Otros | E112: C$50.00/litro alcohol
C113: 2204.10.00.00.00 | D113: - Vino espumoso | E113: C$50.00/litro alcohol
C114: 2204.21.00.00.00 | D114: - - En recipientes con capacidad inferior o igual a 2 l | E114: C$50.00/litro alcohol
C115: 2204.22.00.00.00 | D115: - - En recipientes con capacidad superior a 2 l pero inferior o igual a 10 l | E115: C$50.00/litro alcohol
C116: 2204.29.00.00.00 | D116: - - Los demás | E116: C$50.00/litro alcohol
C117: 2204.30.00.00.00 | D117: - Los demás mostos de uva | E117: C$50.00/litro alcohol
C118: 2205.10.00.00.00 | D118: - En recipientes con capacidad inferior o igual a 2 l | E118: C$50.00/litro alcohol
C119: 2205.90.00.00.00 | D119: - Los demás | E119: C$50.00/litro alcohol
C120: 2206.00.00.00.00 | D120: LAS DEMÁS BEBIDAS FERMENTADAS (POR EJEMPLO: SIDRA, PERADA, AGUAMIEL, SAKE); MEZCLAS DE BEBIDAS FERMENTADAS Y MEZCLAS DE BEBIDAS FERMENTADAS Y BEBIDAS NO ALCOHÓLICAS, NO EXPRESADAS NI COMPRENDIDAS EN OTRA PARTE | E120: C$50.00/litro alcohol
C121: 2207.10.10.00.00 | D121: - - Alcohol etílico absoluto | E121: C$50.00/litro alcohol
... C139: 2208.90.90.00.99 | D139: - - - - Los demás | E139: C$50.00/litro alcohol

Sheet Anexo I
C2: LEY N°. 987 – LEY DE REFORMAS Y ADICIONES A LA LEY N°. 822, LEY DE CONCERTACIÓN TRIBUTARIA
C3: ANEXO I – LISTA DE BIENES DE CONSUMO GRAVADOS CON ISC
C4: La Gaceta, Diario Oficial N°. 41 del 28 de febrero de 2019
C5: CÓDIGO | D5: DESCRIPCIÓN | E5: ISC 2019 | F5: ISC 2020 | G5: ISC 2021 | H5: Reformado Alícuota 0%
C6: 0207.24.00.00.00 | D6: - - Sin trocear, frescos o refrigerados | E6: 25 | F6: 25 | G6: 25 | H6: Reformado
C7: 0207.25.00.00.00 | D7: - - Sin trocear, congelados | E7: 25 | F7: 25 | G7: 25 | H7: Reformado
C8: 0207.27.90.00.10 | D8: - - - - Pechuga deshuesada | E8: 20 | F8: 20 | G8: 20 | H8: =+IFERROR(VLOOKUP(C8,'Reforma 1279'!C:E,3,FALSE),"-") -> -
C9: 0207.27.90.00.20 | D9: - - - - Pierna deshuesada | E9: 20 | F9: 20 | G9: 20 | H9: =+IFERROR(VLOOKUP(C9,'Reforma 1279'!C:E,3,FALSE),"-") -> -
C10: 0207.27.90.00.30 | D10: - - - - Carne molida | E10: 20 | F10: 20 | G10: 20 | H10: =+IFERROR(VLOOKUP(C10,'Reforma 1279'!C:E,3,FALSE),"-") -> -
C11: 0207.27.90.00.40 | D11: - - - - Trozos con hueso | E11: 20 | F11: 20 | G11: 20 | H11: =+IFERROR(VLOOKUP(C11,'Reforma 1279'!C:E,3,FALSE),"-") -> -
C12: 0207.27.90.00.90 | D12: - - - - Otros | E12: 20 | F12: 20 | G12: 20 | H12: =+IFERROR(VLOOKUP(C12,'Reforma 1279'!C:E,3,FALSE),"-") -> -
C13: 0207.42.00.00.00 | D13: - - Sin trocear, congelados | E13: 15 | F13: 15 | G13: 15 | H13: =+IFERROR(VLOOKUP(C13,'Reforma 1279'!C:E,3,FALSE),"-") -> -
C14: 0207.45.10.00.00 | D14: - - - En pasta, deshuesados mecánicamente | E14: 15 | F14: 15 | G14: 15 | H14: =+IFERROR(VLOOKUP(C14,'Reforma 1279'!C:E,3,FALSE),"-") -> -
C15: 0207.45.90.00.00 | D15: - - - Otros | E15: 15 | F15: 15 | G15: 15 | H15: =+IFERROR(VLOOKUP(C15,'Reforma 1279'!C:E,3,FALSE),"-") -> -
C16: 0207.52.00.00.00 | D16: - - Sin trocear, congelados | E16: 15 | F16: 15 | G16: 15 | H16: =+IFERROR(VLOOKUP(C16,'Reforma 1279'!C:E,3,FALSE),"-") -> -
C17: 0207.55.10.00.00 | D17: - - - En pasta, deshuesados mecánicamente | E17: 15 | F17: 15 | G17: 15 | H17: =+IFERROR(VLOOKUP(C17,'Reforma 1279'!C:E,3,FALSE),"-") -> -
C18: 0207.55.90.00.00 | D18: - - - Otros | E18: 15 | F18: 15 | G18: 15 | H18: =+IFERROR(VLOOKUP(C18,'Reforma 1279'!C:E,3,FALSE),"-") -> -
C19: 0207.60.20.00.00 | D19: - - Sin trocear, congelados | E19: 15 | F19: 15 | G19: 15 | H19: =+IFERROR(VLOOKUP(C19,'Reforma 1279'!C:E,3,FALSE),"-") -> -
... C93: 0713.10.90.00.00 | D93: - - Otras | E93: 15 | F93: 15 | G93: 15 | H93: =+IFERROR(VLOOKUP(C93,'Reforma 1279'!C:E,3,FALSE),"-") -> -
C94: 0802.11.00.00.00 | D94: - - Con cáscara | E94: 15 | F94: 15 | G94: 15 | H94: Reformado
C95: 0802.21.00.00.00 | D95: - - Con cáscara | E95: 10 | F95: 10 | G95: 10 | H95: Reformado
C96: 0802.22.00.00.00 | D96: - - Sin cáscara | E96: 10 | F96: 10 | G96: 10 | H96: Reformado
C97: 0802.31.00.00.00 | D97: - - Con cáscara | E97: 10 | F97: 10 | G97: 10 | H97: Reformado
C98: 0802.41.00.00.00 | D98: - - Con cáscara | E98: 15 | F98: 15 | G98: 15 | H98: Reformado
C99: 0802.42.00.00.00 | D99: - - Sin cáscara | E99: 15 | F99: 15 | G99: 15 | H99: Reformado
C100: 0802.51.00.00.00 | D100: - - Con cáscara | E100: 15 | F100: 15 | G100: 15 | H100: Reformado
C101: 0802.52.00.00.00 | D101: - - Sin cáscara | E101: 15 | F101: 15 | G101: 15 | H101: Reformado
C102: 0802.61.00.00.00 | D102: - - Con cáscara | E102: 10 | F102: 10 | G102: 10 | H102: Reformado
C103: 0802.62.00.00.00 | D103: - - Sin cáscara | E103: 10 | F103: 10 | G103: 10 | H103: Reformado
C104: 0802.70.00.00.00 | D104: - Nueces de cola (Cola spp.) | E104: 15 | F104: 15 | G104: 15 | H104: Reformado
C105: 0802.80.00.00.00 | D105: - Nueces de areca | E105: 15 | F105: 15 | G105: 15 | H105: Reformado
... C113: 0813.10.00.00.00 | D113: - Albaricoques (damascos, chabacanos) | E113: 15 | F113: 15 | G113: 15 | H113: Reformado
C114: 0813.30.10.00.00 | D114: - - En trozos | E114: 15 | F114: 15 | G114: 15 | H114: =+IFERROR(VLOOKUP(C114,'Reforma 1279'!C:E,3,FALSE),"-") -> -
C115: 0813.30.90.00.00 | D115: - - Otras | E115: 15 | F115: 15 | G115: 15 | H115: Reformado
C116: 1211.20.20.00.00 | D116: - - Refrigeradas o congeladas | E116: 25 | F116: 25 | G116: 25 | H116: =+IFERROR(VLOOKUP(C116,'Reforma 1279'!C:E,3,FALSE),"-") -> -
C117: 1211.90.92.10.00 | D117: - - - - Partes comestibles de plantas | E117: 25 | F117: 25 | G117: 25 | H117: =+IFERROR(VLOOKUP(C117,'Reforma 1279'!C:E,3,FALSE),"-") -> -
C118: 1601.00.20.00.00 | D118: - De aves de la partida 01.05 | E118: 10 | F118: 10 | G118: 10 | H118: =+IFERROR(VLOOKUP(C118,'Reforma 1279'!C:E,3,FALSE),"-") -> -
C119: 1601.00.30.00.00 | D119: - De porcino | E119: 10 | F119: 10 | G119: 10 | H119: =+IFERROR(VLOOKUP(C119,'Reforma 1279'!C:E,3,FALSE),"-") -> -
C120: 1601.00.90.00.00 | D120: - Mezclas | E120: 10 | F120: 10 | G120: 10 | H120: =+IFERROR(VLOOKUP(C120,'Reforma 1279'!C:E,3,FALSE),"-") -> -
C121: 1603.00.00.00.00 | D121: EXTRACTOS Y JUGOS DE CARNE, PESCADO O DE CRUSTÁCEOS, MOLUSCOS O DEMÁS INVERTEBRADOS ACUÁTICOS | E121: 10 | F121: 10 | G121: 10 | H121: =+IFERROR(VLOOKUP(C121,'Reforma 1279'!C:E,3,FALSE),"-") -> -
...

Sheet Reforma 1279
C2: Articulo segundo: Modificación Tasas del ISC
C4: Reformese las alicuotas del ISC en las posiciones arancelarias del Anexo I de la Ley N° 822, Ley de Concertación Tributaria, publicación en la Gaceta , Diario Oficial N° 241 del 17 de diciembre de 2012, de los suguientes bienes, las que se leerán así:
C6: Código SAC | D6: Descripción | E6: Alícuota ISC
C7: 0207.24.00.00.00 | D7: Pavo fresco o refrigerado | E7: 0
C8: 0207.25.00.00.00 | D8: Pavo congelado | E8: 0
C9: 0207.27.90.00.00 | D9: Pavo en trozos, congelado | E9: 0
C10: 0802.51.00.00.00 | D10: Pistachos con cáscara | E10: 0
C11: 0802.52.00.00.00 | D11: Pistachos sin cáscara | E11: 0
C12: 0802.11.00.00.00 | D12: Almendras con cáscara | E12: 0
C13: 0806.10.00.00.00 | D13: Uvas frescas | E13: 0
C14: 0808.10.00.00.00 | D14: Manzanas frescas | E14: 0
C15: 0808.30.00.00.00 | D15: Peras frescas | E15: 0
C16: 0813.30.90.00.00 | D16: Manzanas secas | E16: 0
C17: 0802.21.00.00.00 | D17: Avellanas con cáscara | E17: 0
C18: 0802.22.00.00.00 | D18: Avellanas sin cáscara | E18: 0
... C25: 0802.80.00.00.00 | D25: Nueces de areca | E25: 0
C26: 0803.90.12.00.10 | D26: Bananas secas orgánicas | E26: 0 | G26: Reformado | H26: 0803.90.12.00.00 | I26: - - - Secas
C27: 0803.90.12.00.90 | D27: Las demás bananas secas | E27: 0 | G27: Reformado
C28: 0808.40.00.00.00 | D28: Membrillos frescos | E28: 0
C29: 0809.10.00.00.00 | D29: Albaricoques frescos | E29: 0
C30: 0812.90.10.00.00 | D30: Fresas conservadas | E30: 0
C31: 0813.10.00.00.00 | D31: Albaricoques secos | E31: 0
